Workbook

Sheet Products2
A1: inv | B1: date | C1: decade | D1: group | E1: vigade | F1: quinade | G1: slaves | H1: beesten | I1: paarden | J1: schapen | K1: ploeg | L1: koornharp | M1: schuijt | N1: emmers | O1: graaven | P1: geweer | Q1: brandewijnskeetels | R1: waagen | S1: aambeeld | T1: bankschroef | U1: balans | V1: tang | W1: stoven | X1: kadels | Y1: stoel | Z1: broek | AA1: strijkijsters | AB1: boeken | AC1: horlogie | AD1: snuijfdoos | AE1: schilderij | AF1: spiegel | AG1: vogelkooi | AH1: ring
A2: INV0001 | B2: 1673 | C2: 1700 | D2: 1 | E2: 1700 | G2: 0 | H2: 4 | I2: 0 | J2: 0 | K2: 0 | L2: 0 | M2: 0 | N2: 0 | O2: 2 | P2: 1 | Q2: 0 | R2: 0 | S2: 0 | T2: 0 | U2: 0 | V2: 1 | W2: 0 | X2: 0 | Y2: 0 | Z2: 1 | AA2: 0 | AB2: 0 | AC2: 0 | AD2: 0 | AE2: 2 | AF2: 0 | AG2: 0 | AH2: 2
A3: INV0012 | B3: 1685 | C3: 1700 | D3: 3 | E3: 1700 | G3: 12 | H3: 70 | I3: 6 | J3: 425 | K3: 0 | L3: 0 | M3: 0 | N3: 2 | O3: 0 | P3: 0 | Q3: 0 | R3: 0 | S3: 0 | T3: 0 | U3: 0 | V3: 2 | W3: 0 | X3: 2 | Y3: 20 | Z3: 0 | AA3: 0 | AB3: 5 | AC3: 0 | AD3: 0 | AE3: 0 | AF3: 2 | AG3: 0 | AH3: 0
A4: INV2444 | B4: 1687 | C4: 1700 | D4: 1 | E4: 1700 | G4: 0 | H4: 6 | I4: 0 | J4: 70 | K4: 0 | L4: 0 | M4: 0 | N4: 0 | O4: 0 | P4: 0 | Q4: 0 | R4: 0 | S4: 0 | T4: 0 | U4: 0 | V4: 0 | W4: 0 | X4: 0 | Y4: 0 | Z4: 0 | AA4: 0 | AB4: 0 | AC4: 0 | AD4: 0 | AE4: 0 | AF4: 0 | AG4: 0 | AH4: 0
A5: INV0044 | B5: 1688 | C5: 1700 | D5: 2 | E5: 1700 | G5: 1 | H5: 12 | I5: 2 | J5: 550 | K5: 2 | L5: 0 | M5: 0 | N5: 1 | O5: 2 | P5: 1 | Q5: 0 | R5: 1 | S5: 0 | T5: 0 | U5: 0 | V5: 1 | W5: 0 | X5: 0 | Y5: 0 | Z5: 0 | AA5: 1 | AB5: 0 | AC5: 0 | AD5: 0 | AE5: 0 | AF5: 0 | AG5: 0 | AH5: 0
A6: INV2445 | B6: 1689 | C6: 1700 | D6: 1 | E6: 1700 | G6: 0 | H6: 0 | I6: 0 | J6: 99 | K6: 0 | L6: 0 | M6: 0 | N6: 0 | O6: 0 | P6: 0 | Q6: 0 | R6: 0 | S6: 0 | T6: 0 | U6: 0 | V6: 0 | W6: 0 | X6: 1 | Y6: 0 | Z6: 1 | AA6: 0 | AB6: 0 | AC6: 0 | AD6: 0 | AE6: 0 | AF6: 0 | AG6: 0 | AH6: 0
A7: INV2446 | B7: 1689 | C7: 1700 | D7: 2 | E7: 1700 | G7: 1 | H7: 11 | I7: 2 | J7: 200 | K7: 1 | L7: 0 | M7: 0 | N7: 0 | O7: 0 | P7: 0 | Q7: 0 | R7: 1 | S7: 0 | T7: 0 | U7: 0 | V7: 0 | W7: 0 | X7: 0 | Y7: 0 | Z7: 0 | AA7: 0 | AB7: 0 | AC7: 0 | AD7: 0 | AE7: 0 | AF7: 0 | AG7: 0 | AH7: 0
A8: INV2447 | B8: 1689 | C8: 1700 | D8: 2 | E8: 1700 | G8: 1 | H8: 32 | I8: 3 | J8: 100 | K8: 1 | L8: 0 | M8: 0 | N8: 0 | O8: 0 | P8: 0 | Q8: 0 | R8: 1 | S8: 0 | T8: 0 | U8: 0 | V8: 0 | W8: 0 | X8: 0 | Y8: 0 | Z8: 0 | AA8: 0 | AB8: 0 | AC8: 0 | AD8: 0 | AE8: 0 | AF8: 0 | AG8: 0 | AH8: 0
A9: INV2448 | B9: 1689 | C9: 1700 | D9: 1 | E9: 1700 | G9: 0 | H9: 7 | I9: 0 | J9: 0 | K9: 1 | L9: 0 | M9: 0 | N9: 0 | O9: 0 | P9: 0 | Q9: 0 | R9: 1 | S9: 0 | T9: 0 | U9: 0 | V9: 0 | W9: 0 | X9: 0 | Y9: 0 | Z9: 0 | AA9: 0 | AB9: 0 | AC9: 0 | AD9: 0 | AE9: 0 | AF9: 0 | AG9: 0 | AH9: 0
A10: INV2449 | B10: 1689 | C10: 1700 | D10: 1 | E10: 1700 | G10: 0 | H10: 40 | I10: 2 | J10: 0 | K10: 1 | L10: 0 | M10: 0 | N10: 0 | O10: 0 | P10: 0 | Q10: 0 | R10: 1 | S10: 0 | T10: 0 | U10: 0 | V10: 0 | W10: 0 | X10: 0 | Y10: 0 | Z10: 0 | AA10: 0 | AB10: 0 | AC10: 0 | AD10: 0 | AE10: 0 | AF10: 0 | AG10: 0 | AH10: 0
A11: INV2450 | B11: 1689 | C11: 1700 | D11: 1 | E11: 1700 | G11: 0 | H11: 30 | I11: 3 | J11: 250 | K11: 1 | L11: 0 | M11: 0 | N11: 0 | O11: 0 | P11: 0 | Q11: 0 | R11: 1 | S11: 0 | T11: 0 | U11: 0 | V11: 0 | W11: 0 | X11: 0 | Y11: 0 | Z11: 0 | AA11: 0 | AB11: 0 | AC11: 0 | AD11: 0 | AE11: 0 | AF11: 0 | AG11: 0 | AH11: 0
A12: INV2451 | B12: 1689 | C12: 1700 | D12: 1 | E12: 1700 | G12: 0 | H12: 13 | I12: 2 | J12: 0 | K12: 1 | L12: 0 | M12: 0 | N12: 0 | O12: 0 | P12: 0 | Q12: 0 | R12: 1 | S12: 0 | T12: 0 | U12: 0 | V12: 0 | W12: 0 | X12: 0 | Y12: 0 | Z12: 0 | AA12: 0 | AB12: 0 | AC12: 0 | AD12: 0 | AE12: 0 | AF12: 0 | AG12: 0 | AH12: 0
A13: INV2452 | B13: 1689 | C13: 1700 | D13: 1 | E13: 1700 | G13: 0 | H13: 17 | I13: 0 | J13: 20 | K13: 1 | L13: 0 | M13: 0 | N13: 3 | O13: 1 | P13: 1 | Q13: 0 | R13: 0 | S13: 0 | T13: 0 | U13: 0 | V13: 1 | W13: 0 | X13: 0 | Y13: 0 | Z13: 0 | AA13: 0 | AB13: 0 | AC13: 0 | AD13: 0 | AE13: 0 | AF13: 0 | AG13: 0 | AH13: 0
... A18: INV0082 | B18: 1692 | C18: 1700 | D18: 1 | E18: 1700 | G18: 0 | H18: 0 | I18: 0 | J18: 0 | K18: 0 | L18: 0 | M18: 0 | N18: 0 | O18: 0 | P18: 0 | Q18: 0 | R18: 0 | S18: 0 | T18: 0 | U18: 0 | V18: 0 | W18: 0 | X18: 0 | Y18: 0 | Z18: 0 | AA18: 0 | AB18: 0 | AC18: 0 | AD18: 0 | AE18: 0 | AF18: 0 | AG18: 0 | AH18: 0
A19: INV0054 | B19: 1693 | C19: 1700 | D19: 1 | E19: 1700 | F19: 1697 | G19: 0 | H19: 4 | I19: 3 | J19: 300 | K19: 0 | L19: 0 | M19: 0 | N19: 2 | O19: 2 | P19: 1 | Q19: 0 | R19: 1 | S19: 0 | T19: 0 | U19: 0 | V19: 0 | W19: 0 | X19: 0 | Y19: 3 | Z19: 0 | AA19: 1 | AB19: 0 | AC19: 0 | AD19: 0 | AE19: 0 | AF19: 2 | AG19: 1 | AH19: 0
A20: INV0064 | B20: 1693 | C20: 1700 | D20: 3 | E20: 1700 | F20: 1697 | G20: 9 | H20: 175 | I20: 0 | J20: 1700 | K20: 0 | L20: 0 | M20: 0 | N20: 0 | O20: 0 | P20: 0 | Q20: 0 | R20: 0 | S20: 0 | T20: 0 | U20: 0 | V20: 0 | W20: 0 | X20: 0 | Y20: 0 | Z20: 0 | AA20: 0 | AB20: 0 | AC20: 0 | AD20: 0 | AE20: 0 | AF20: 0 | AG20: 0 | AH20: 0
A21: INV0075 | B21: 1693 | C21: 1700 | D21: 3 | E21: 1700 | F21: 1697 | G21: 5 | H21: 0 | I21: 0 | J21: 0 | K21: 0 | L21: 0 | M21: 0 | N21: 0 | O21: 0 | P21: 2 | Q21: 0 | R21: 0 | S21: 0 | T21: 0 | U21: 0 | V21: 1 | W21: 0 | X21: 0 | Y21: 10 | Z21: 0 | AA21: 3 | AB21: 0 | AC21: 0 | AD21: 0 | AE21: 0 | AF21: 1 | AG21: 0 | AH21: 4
A22: INV0002 | B22: 1694 | C22: 1700 | D22: 3 | E22: 1700 | F22: 1697 | G22: 5 | H22: 10 | I22: 8 | J22: 300 | K22: 1 | L22: 0 | M22: 0 | N22: 4 | O22: 4 | P22: 3 | Q22: 0 | R22: 2 | S22: 0 | T22: 0 | U22: 0 | V22: 1 | W22: 0 | X22: 2 | Y22: 14 | Z22: 0 | AA22: 3 | AB22: 0 | AC22: 0 | AD22: 0 | AE22: 0 | AF22: 1 | AG22: 0 | AH22: 0
A23: INV0003 | B23: 1694 | C23: 1700 | D23: 2 | E23: 1700 | F23: 1697 | G23: 2 | H23: 42 | I23: 5 | J23: 350 | K23: 0 | L23: 0 | M23: 0 | N23: 0 | O23: 0 | P23: 0 | Q23: 0 | R23: 0 | S23: 0 | T23: 0 | U23: 0 | V23: 0 | W23: 0 | X23: 0 | Y23: 0 | Z23: 0 | AA23: 0 | AB23: 0 | AC23: 0 | AD23: 0 | AE23: 0 | AF23: 0 | AG23: 0 | AH23: 0
A24: INV0004 | B24: 1695 | C24: 1700 | D24: 2 | E24: 1700 | F24: 1697 | G24: 4 | H24: 40 | I24: 3 | J24: 60 | K24: 1 | L24: 0 | M24: 0 | N24: 0 | O24: 0 | P24: 0 | Q24: 0 | R24: 1 | S24: 0 | T24: 0 | U24: 0 | V24: 0 | W24: 0 | X24: 0 | Y24: 0 | Z24: 0 | AA24: 0 | AB24: 0 | AC24: 0 | AD24: 0 | AE24: 0 | AF24: 0 | AG24: 0 | AH24: 0
A25: INV0005 | B25: 1695 | C25: 1700 | D25: 2 | E25: 1700 | F25: 1697 | G25: 1 | H25: 0 | I25: 0 | J25: 0 | K25: 0 | L25: 0 | M25: 0 | N25: 0 | O25: 0 | P25: 0 | Q25: 0 | R25: 0 | S25: 0 | T25: 0 | U25: 0 | V25: 2 | W25: 0 | X25: 4 | Y25: 12 | Z25: 0 | AA25: 2 | AB25: 0 | AC25: 1 | AD25: 0 | AE25: 5 | AF25: 19 | AG25: 0 | AH25: 0
A26: INV0006 | B26: 1695 | C26: 1700 | D26: 2 | E26: 1700 | F26: 1697 | G26: 1 | H26: 0 | I26: 1 | J26: 0 | K26: 0 | L26: 0 | M26: 0 | N26: 0 | O26: 0 | P26: 1 | Q26: 0 | R26: 0 | S26: 0 | T26: 0 | U26: 0 | V26: 0 | W26: 0 | X26: 0 | Y26: 0 | Z26: 0 | AA26: 0 | AB26: 0 | AC26: 0 | AD26: 0 | AE26: 0 | AF26: 0 | AG26: 0 | AH26: 0
A27: INV0007 | B27: 1695 | C27: 1700 | D27: 3 | E27: 1700 | F27: 1697 | G27: 9 | H27: 50 | I27: 3 | J27: 600 | K27: 0 | L27: 0 | M27: 0 | N27: 0 | O27: 0 | P27: 0 | Q27: 0 | R27: 0 | S27: 0 | T27: 0 | U27: 0 | V27: 0 | W27: 0 | X27: 0 | Y27: 0 | Z27: 0 | AA27: 0 | AB27: 0 | AC27: 0 | AD27: 0 | AE27: 0 | AF27: 0 | AG27: 0 | AH27: 0
A28: INV0008 | B28: 1696 | C28: 1700 | D28: 2 | E28: 1700 | F28: 1697 | G28: 2 | H28: 8 | I28: 0 | J28: 0 | K28: 0 | L28: 0 | M28: 0 | N28: 0 | O28: 1 | P28: 1 | Q28: 0 | R28: 0 | S28: 0 | T28: 0 | U28: 0 | V28: 0 | W28: 0 | X28: 1 | Y28: 2 | Z28: 0 | AA28: 0 | AB28: 0 | AC28: 0 | AD28: 0 | AE28: 0 | AF28: 0 | AG28: 0 | AH28: 0
A29: INV0009 | B29: 1696 | C29: 1700 | D29: 1 | E29: 1700 | F29: 1697 | G29: 0 | H29: 36 | I29: 2 | J29: 0 | K29: 0 | L29: 0 | M29: 0 | N29: 0 | O29: 0 | P29: 0 | Q29: 0 | R29: 0 | S29: 0 | T29: 0 | U29: 0 | V29: 0 | W29: 0 | X29: 0 | Y29: 0 | Z29: 0 | AA29: 0 | AB29: 0 | AC29: 0 | AD29: 0 | AE29: 0 | AF29: 0 | AG29: 0 | AH29: 0
A30: INV0010 | B30: 1696 | C30: 1700 | D30: 2 | E30: 1700 | F30: 1697 | G30: 4 | H30: 120 | I30: 5 | J30: 250 | K30: 0 | L30: 0 | M30: 0 | N30: 0 | O30: 0 | P30: 0 | Q30: 0 | R30: 0 | S30: 0 | T30: 0 | U30: 0 | V30: 0 | W30: 0 | X30: 0 | Y30: 0 | Z30: 0 | AA30: 0 | AB30: 0 | AC30: 0 | AD30: 0 | AE30: 0 | AF30: 0 | AG30: 0 | AH30: 0
... A2323: INV2571 | B2323: 1802 | C2323: 1806 | D2323: 1 | E2323: 1806 | F2323: 1802 | G2323: 0 | H2323: 0 | I2323: 0 | J2323: 0 | K2323: 0 | L2323: 0 | M2323: 0 | N2323: 0 | O2323: 0 | P2323: 0 | Q2323: 0 | R2323: 0 | S2323: 0 | T2323: 0 | U2323: 0 | V2323: 0 | W2323: 0 | X2323: 0 | Y2323: 0 | Z2323: 0 | AA2323: 0 | AB2323: 0 | AC2323: 0 | AD2323: 0 | AE2323: 0 | AF2323: 0 | AG2323: 0 | AH2323: 0
A2324: INV1087 | B2324: 1803 | C2324: 1806 | D2324: 1 | E2324: 1806 | G2324: 0 | H2324: 0 | I2324: 0 | J2324: 0 | K2324: 0 | L2324: 0 | M2324: 0 | N2324: 0 | O2324: 0 | P2324: 0 | Q2324: 0 | R2324: 0 | S2324: 0 | T2324: 0 | U2324: 0 | V2324: 0 | W2324: 0 | X2324: 0 | Y2324: 0 | Z2324: 24 | AA2324: 0 | AB2324: 25 | AC2324: 1 | AD2324: 2 | AE2324: 0 | AF2324: 0 | AG2324: 0 | AH2324: 2
A2325: INV1091 | B2325: 1803 | C2325: 1806 | D2325: 2 | E2325: 1806 | G2325: 2 | H2325: 0 | I2325: 1 | J2325: 0 | K2325: 0 | L2325: 0 | M2325: 0 | N2325: 0 | O2325: 0 | P2325: 0 | Q2325: 0 | R2325: 0 | S2325: 0 | T2325: 0 | U2325: 0 | V2325: 0 | W2325: 0 | X2325: 2 | Y2325: 0 | Z2325: 0 | AA2325: 1 | AB2325: 5 | AC2325: 0 | AD2325: 0 | AE2325: 0 | AF2325: 0 | AG2325: 0 | AH2325: 0
A2326: INV1096 | B2326: 1803 | C2326: 1806 | D2326: 2 | E2326: 1806 | G2326: 3 | H2326: 0 | I2326: 0 | J2326: 0 | K2326: 0 | L2326: 0 | M2326: 0 | N2326: 0 | O2326: 0 | P2326: 0 | Q2326: 0 | R2326: 0 | S2326: 0 | T2326: 0 | U2326: 0 | V2326: 0 | W2326: 0 | X2326: 0 | Y2326: 0 | Z2326: 12 | AA2326: 0 | AB2326: 0 | AC2326: 0 | AD2326: 0 | AE2326: 0 | AF2326: 0 | AG2326: 0 | AH2326: 0
A2327: INV1102 | B2327: 1803 | C2327: 1806 | D2327: 3 | E2327: 1806 | G2327: 7 | H2327: 34 | I2327: 15 | J2327: 2 | K2327: 3 | L2327: 1 | M2327: 0 | N2327: 2 | O2327: 3 | P2327: 1 | Q2327: 0 | R2327: 0 | S2327: 0 | T2327: 1 | U2327: 0 | V2327: 0 | W2327: 0 | X2327: 4 | Y2327: 10 | Z2327: 0 | AA2327: 0 | AB2327: 0 | AC2327: 1 | AD2327: 0 | AE2327: 6 | AF2327: 0 | AG2327: 2 | AH2327: 0
A2328: INV1103 | B2328: 1803 | C2328: 1806 | D2328: 2 | E2328: 1806 | G2328: 3 | H2328: 32 | I2328: 6 | J2328: 240 | K2328: 1 | L2328: 0 | M2328: 0 | N2328: 2 | O2328: 2 | P2328: 1 | Q2328: 0 | R2328: 0 | S2328: 0 | T2328: 0 | U2328: 0 | V2328: 0 | W2328: 0 | X2328: 0 | Y2328: 4 | Z2328: 0 | AA2328: 1 | AB2328: 0 | AC2328: 0 | AD2328: 0 | AE2328: 0 | AF2328: 0 | AG2328: 0 | AH2328: 0
A2329: INV1113 | B2329: 1803 | C2329: 1806 | D2329: 2 | E2329: 1806 | G2329: 3 | H2329: 15 | I2329: 1 | J2329: 46 | K2329: 2 | L2329: 0 | M2329: 0 | N2329: 4 | O2329: 2 | P2329: 3 | Q2329: 0 | R2329: 1 | S2329: 1 | T2329: 1 | U2329: 0 | V2329: 4 | W2329: 0 | X2329: 2 | Y2329: 3 | Z2329: 0 | AA2329: 0 | AB2329: 5 | AC2329: 1 | AD2329: 1 | AE2329: 0 | AF2329: 0 | AG2329: 0 | AH2329: 0
A2330: INV1117 | B2330: 1803 | C2330: 1806 | D2330: 3 | E2330: 1806 | G2330: 6 | H2330: 12 | I2330: 0 | J2330: 0 | K2330: 1 | L2330: 0 | M2330: 0 | N2330: 1 | O2330: 0 | P2330: 0 | Q2330: 0 | R2330: 0 | S2330: 0 | T2330: 0 | U2330: 0 | V2330: 0 | W2330: 0 | X2330: 2 | Y2330: 6 | Z2330: 0 | AA2330: 0 | AB2330: 5 | AC2330: 1 | AD2330: 0 | AE2330: 0 | AF2330: 0 | AG2330: 0 | AH2330: 0
A2331: INV1120 | B2331: 1803 | C2331: 1806 | D2331: 2 | E2331: 1806 | G2331: 2 | H2331: 17 | I2331: 7 | J2331: 0 | K2331: 1 | L2331: 0 | M2331: 0 | N2331: 3 | O2331: 3 | P2331: 1 | Q2331: 0 | R2331: 0 | S2331: 0 | T2331: 0 | U2331: 0 | V2331: 0 | W2331: 0 | X2331: 0 | Y2331: 2 | Z2331: 0 | AA2331: 1 | AB2331: 0 | AC2331: 0 | AD2331: 0 | AE2331: 0 | AF2331: 0 | AG2331: 0 | AH2331: 0
A2332: INV1146 | B2332: 1803 | C2332: 1806 | D2332: 3 | E2332: 1806 | G2332: 7 | H2332: 0 | I2332: 0 | J2332: 0 | K2332: 0 | L2332: 0 | M2332: 0 | N2332: 0 | O2332: 0 | P2332: 0 | Q2332: 0 | R2332: 0 | S2332: 0 | T2332: 0 | U2332: 1 | V2332: 0 | W2332: 0 | X2332: 0 | Y2332: 8 | Z2332: 0 | AA2332: 1 | AB2332: 0 | AC2332: 0 | AD2332: 1 | AE2332: 8 | AF2332: 4 | AG2332: 3 | AH2332: 0
A2333: INV1156 | B2333: 1803 | C2333: 1806 | D2333: 3 | E2333: 1806 | G2333: 7 | H2333: 0 | I2333: 0 | J2333: 0 | K2333: 0 | L2333: 0 | M2333: 0 | N2333: 0 | O2333: 0 | P2333: 0 | Q2333: 0 | R2333: 0 | S2333: 0 | T2333: 0 | U2333: 0 | V2333: 0 | W2333: 0 | X2333: 0 | Y2333: 12 | Z2333: 2 | AA2333: 0 | AB2333: 2 | AC2333: 0 | AD2333: 0 | AE2333: 6 | AF2333: 0 | AG2333: 0 | AH2333: 0
A2334: INV1157 | B2334: 1803 | C2334: 1806 | D2334: 3 | E2334: 1806 | G2334: 8 | H2334: 4 | I2334: 0 | J2334: 0 | K2334: 0 | L2334: 0 | M2334: 0 | N2334: 4 | O2334: 0 | P2334: 0 | Q2334: 0 | R2334: 0 | S2334: 0 | T2334: 1 | U2334: 4 | V2334: 4 | W2334: 1 | X2334: 13 | Y2334: 49 | Z2334: 0 | AA2334: 6 | AB2334: 0 | AC2334: 2 | AD2334: 4 | AE2334: 57 | AF2334: 24 | AG2334: 7 | AH2334: 3
A2335: INV1158 | B2335: 1803 | C2335: 1806 | D2335: 2 | E2335: 1806 | G2335: 1 | H2335: 0 | I2335: 0 | J2335: 0 | K2335: 0 | L2335: 0 | M2335: 0 | N2335: 2 | O2335: 0 | P2335: 0 | Q2335: 0 | R2335: 0 | S2335: 0 | T2335: 0 | U2335: 1 | V2335: 0 | W2335: 3 | X2335: 1 | Y2335: 12 | Z2335: 0 | AA2335: 0 | AB2335: 1 | AC2335: 2 | AD2335: 0 | AE2335: 2 | AF2335: 2 | AG2335: 0 | AH2335: 0
... A2578: INV2338 | B2578: 1806 | C2578: 1806 | D2578: 4 | E2578: 1806 | G2578: 24 | H2578: 0 | I2578: 0 | J2578: 0 | K2578: 0 | L2578: 0 | M2578: 0 | N2578: 0 | O2578: 0 | P2578: 0 | Q2578: 0 | R2578: 0 | S2578: 0 | T2578: 0 | U2578: 0 | V2578: 0 | W2578: 0 | X2578: 0 | Y2578: 0 | Z2578: 0 | AA2578: 0 | AB2578: 0 | AC2578: 0 | AD2578: 0 | AE2578: 0 | AF2578: 0 | AG2578: 0 | AH2578: 0

Sheet Prices2
A1: stats | B1: Slaves | C1: Cattle | D1: Horses | E1: Sheep | F1: Ploughs | G1: Corn sieves | H1: Boats | I1: Buckets | J1: Spades | K1: Guns | L1: Brandy stills | M1: Wagons | N1: Anvil | O1: Bench vice | P1: Balance | Q1: Fire-tong | R1: Oven | S1: Bedstead | T1: Chairs | U1: Trousers | V1: Irons | W1: Books | X1: Clocks and watches | Y1: Snuff-box | Z1: Paintings | AA1: Mirrors | AB1: Bird cage | AC1: Gold rings
A2: N | B2: 1102 | C2: 3401 | D2: 650 | E2: 909 | F2: 143 | G2: 18 | H2: 11 | I2: 263 | J2: 62 | K2: 250 | L2: 46 | M2: 279 | N2: 7 | O2: 10 | P2: 171 | Q2: 74 | R2: 80 | S2: 348 | T2: 1250 | U2: 57 | V2: 140 | W2: 326 | X2: 49 | Y2: 64 | Z2: 548 | AA2: 356 | AB2: 55 | AC2: 110
A3: sum | B3: 6716319 | C3: 1529962 | D3: 631379.2 | E3: 51431.65 | F3: 54721 | G3: 20508 | H3: 18502 | I3: 12842.52 | J3: 1898.496 | K3: 52879.9 | L3: 83748 | M3: 554226 | N3: 6480 | O3: 3612 | P3: 34441 | Q3: 3193.5 | R3: 1943.814 | S3: 32861 | T3: 75512.12 | U3: 4294 | V3: 8037 | W3: 17437.95 | X3: 42204 | Y3: 9507.5 | Z3: 59764.28 | AA3: 84812.8 | AB3: 4890.6 | AC3: 38722
A4: mean | B4: 6094.663 | C4: 449.8565 | D4: 971.3526 | E4: 56.58047 | F4: 382.6643 | G4: 1139.333 | H4: 1682 | I4: 48.83088 | J4: 30.62091 | K4: 211.5196 | L4: 1820.609 | M4: 1986.473 | N4: 925.7143 | O4: 361.2 | P4: 201.4094 | Q4: 43.15541 | R4: 24.29768 | S4: 94.42816 | T4: 60.4097 | U4: 75.33333 | V4: 57.40714 | W4: 53.49065 | X4: 861.3061 | Y4: 148.5547 | Z4: 109.0589 | AA4: 238.2382 | AB4: 88.92 | AC4: 352.0182
A5: sd | B5: 3535.873 | C5: 251.1412 | D5: 808.3029 | E5: 30.29686 | F5: 264.353 | G5: 542.4216 | H5: 1285.254 | I5: 44.3449 | J5: 18.33612 | K5: 217.9181 | L5: 1450.28 | M5: 1564.008 | N5: 900.5846 | O5: 158.7904 | P5: 279.2055 | Q5: 27.72158 | R5: 21.83574 | S5: 72.19164 | T5: 34.38891 | U5: 51.43289 | V5: 41.09756 | W5: 81.49733 | X5: 1020.61 | Y5: 156.6615 | Z5: 145.0699 | AA5: 334.9988 | AB5: 83.39071 | AC5: 588.9727
A6: min | B6: 48 | C6: 20.4 | D6: 24 | E6: 6.8 | F6: 24 | G6: 120 | H6: 400 | I6: 3 | J6: 4.615385 | K6: 10 | L6: 81 | M6: 8 | N6: 90 | O6: 144 | P6: 6 | Q6: 12 | R6: 2 | S6: 1.5 | T6: 1.2 | U6: 3 | V6: 4 | W6: 1.2 | X6: 12 | Y6: 6 | Z6: 1 | AA6: 3 | AB6: 12 | AC6: 21
A7: max | B7: 32736 | C7: 2016 | D7: 4800 | E7: 141.42 | F7: 1416 | G7: 2112 | H7: 4320 | I7: 378 | J7: 108 | K7: 1602 | L7: 5856 | M7: 9696 | N7: 2400 | O7: 672 | P7: 1776 | Q7: 162 | R7: 108 | S7: 408 | T7: 396 | U7: 270 | V7: 210 | W7: 960 | X7: 4800 | Y7: 828 | Z7: 852 | AA7: 2400 | AB7: 492 | AC7: 3360
A8: p50 | B8: 5412 | C8: 417 | D8: 759 | E8: 48.48 | F8: 312 | G8: 1083 | H8: 1440 | I8: 38 | J8: 27.75 | K8: 150 | L8: 1695 | M8: 1632 | N8: 738 | O8: 342 | P8: 114 | Q8: 36 | R8: 18 | S8: 78 | T8: 54 | U8: 63 | V8: 48 | W8: 32 | X8: 582 | Y8: 100.5 | Z8: 54 | AA8: 108 | AB8: 60 | AC8: 147
A9: mean (rds) | B9: =B4/48 -> 126.97215 | C9: =C4/48 -> 9.3720104 | D9: =D4/48 -> 20.236512 | E9: =E4/48 -> 1.1787598 | F9: =F4/48 -> 7.9721729 | G9: =G4/48 -> 23.736104 | H9: =H4/48 -> 35.041667 | I9: =I4/48 -> 1.01731 | ... AC9: =AC4/48 -> 7.3337125
A10: median (rds) | B10: =B8/48 -> 112.75 | C10: =C8/48 -> 8.6875 | D10: =D8/48 -> 15.8125 | E10: =E8/48 -> 1.01 | F10: =F8/48 -> 6.5 | G10: =G8/48 -> 22.5625 | H10: =H8/48 -> 30 | I10: =I8/48 -> 0.79166667 | ... AC10: =AC8/48 -> 3.0625

Sheet Value2
A1: inv | B1: nr | C1: date | D1: decade | E1: group | F1: vigade | G1: quinade | H1: stb | I1: slawerijks | J1: beestenrijks | K1: paardenrijks | L1: schapenrijks | M1: ploegrijks | N1: harprijks | O1: schuijtrijks | P1: emmersrijks | Q1: gravenrijks | R1: geweerrijks | S1: ketelrijks | T1: wagenrijks | U1: aambeeldrijks | V1: bankschroefrijks | W1: balansrijks | X1: tangrijks | Y1: stovenrijks | Z1: bedrijks | AA1: stoelrijks | AB1: broekenrijks | AC1: strijkijsersrijks | AD1: boekrijks | AE1: horologiesrijks | AF1: doosrijks | AG1: schilderijrijks | AH1: spiegelrijks | AI1: vogelkooijrijks | AJ1: ringrijks | AK1: wealthrijks | AL1: totalns | AN1: nr | AO1: decade | AP1: date | AQ1: total | AS1: date | AT1: total | BE1: Year | BF1: Obs | BG1: Mean | BH1: Lower | BI1: Upper | BM1: date | BN1: total no zero
A2: INV0001 | B2: 1 | C2: 1673 | D2: 1700 | E2: 1 | F2: 1700 | H2: 0 | I2: =Products2!G2*Prices2!B$10 -> 0 | J2: =Products2!H2*Prices2!C$10 -> 34.75 | K2: =Products2!I2*Prices2!D$10 -> 0 | L2: =Products2!J2*Prices2!E$10 -> 0 | M2: =Products2!K2*Prices2!F$10 -> 0 | N2: =Products2!L2*Prices2!G$10 -> 0 | O2: =Products2!M2*Prices2!H$10 -> 0 | P2: =Products2!N2*Prices2!I$10 -> 0 | ... AJ2: =Products2!AH2*Prices2!AC$10 -> 6.125 | AK2: =SUM(I2:AJ2) -> 49.46875 | AL2: =AK2-I2 -> 49.46875 | AN2: 1 | AO2: 1700 | AP2: 1673 | AQ2: 49.46875 | AS2: 1673 | AT2: 49.47 | AX2: graph box total, over(decade) nooutsides | BE2: 1700 | BF2: 71 | BG2: 759.3011 | BH2: 475.7277 | BI2: 1042.875 | BM2: 1673 | BN2: 49.47
A3: INV0012 | B3: 1 | C3: 1685 | D3: 1700 | E3: 3 | F3: 1700 | H3: 0 | I3: =Products2!G3*Prices2!B$10 -> 1353 | J3: =Products2!H3*Prices2!C$10 -> 608.125 | K3: =Products2!I3*Prices2!D$10 -> 94.875 | L3: =Products2!J3*Prices2!E$10 -> 429.25 | M3: =Products2!K3*Prices2!F$10 -> 0 | N3: =Products2!L3*Prices2!G$10 -> 0 | O3: =Products2!M3*Prices2!H$10 -> 0 | P3: =Products2!N3*Prices2!I$10 -> 1.5833333 | ... AJ3: =Products2!AH3*Prices2!AC$10 -> 0 | AK3: =SUM(I3:AJ3) -> 2521.9167 | AL3: =AK3-I3 -> 1168.9167 | AN3: 2 | AO3: 1700 | AP3: 1685 | AQ3: 2521.9167 | AS3: 1685 | AT3: 2521.92 | BE3: 1710 | BF3: 77 | BG3: 1478.792 | BH3: 1001.015 | BI3: 1956.568 | BM3: 1685 | BN3: 2521.92
A4: INV2444 | B4: 1 | C4: 1687 | D4: 1700 | E4: 1 | F4: 1700 | H4: 1 | I4: =Products2!G4*Prices2!B$10 -> 0 | J4: =Products2!H4*Prices2!C$10 -> 52.125 | K4: =Products2!I4*Prices2!D$10 -> 0 | L4: =Products2!J4*Prices2!E$10 -> 70.7 | M4: =Products2!K4*Prices2!F$10 -> 0 | N4: =Products2!L4*Prices2!G$10 -> 0 | O4: =Products2!M4*Prices2!H$10 -> 0 | P4: =Products2!N4*Prices2!I$10 -> 0 | ... AJ4: =Products2!AH4*Prices2!AC$10 -> 0 | AK4: =SUM(I4:AJ4) -> 122.825 | AL4: =AK4-I4 -> 122.825 | AN4: 3 | AO4: 1700 | AP4: 1687 | AQ4: 122.825 | AS4: 1687 | AT4: 122.83 | BE4: 1720 | BF4: 198 | BG4: 1109.55 | BH4: 889.909 | BI4: 1329.192 | BM4: 1687 | BN4: 122.83
A5: INV0044 | B5: 1 | C5: 1688 | D5: 1700 | E5: 2 | F5: 1700 | H5: 1 | I5: =Products2!G5*Prices2!B$10 -> 112.75 | J5: =Products2!H5*Prices2!C$10 -> 104.25 | K5: =Products2!I5*Prices2!D$10 -> 31.625 | L5: =Products2!J5*Prices2!E$10 -> 555.5 | M5: =Products2!K5*Prices2!F$10 -> 13 | N5: =Products2!L5*Prices2!G$10 -> 0 | O5: =Products2!M5*Prices2!H$10 -> 0 | P5: =Products2!N5*Prices2!I$10 -> 0.79166667 | ... AJ5: =Products2!AH5*Prices2!AC$10 -> 0 | AK5: =SUM(I5:AJ5) -> 857.94792 | AL5: =AK5-I5 -> 745.19792 | AN5: 4 | AO5: 1700 | AP5: 1688 | AQ5: 857.94792 | AS5: 1688 | AT5: 857.95 | BE5: 1730 | BF5: 135 | BG5: 1223.558 | BH5: 959.8813 | BI5: 1487.235 | BM5: 1688 | BN5: 857.95
A6: INV2445 | B6: 1 | C6: 1689 | D6: 1700 | E6: 1 | F6: 1700 | H6: 1 | I6: =Products2!G6*Prices2!B$10 -> 0 | J6: =Products2!H6*Prices2!C$10 -> 0 | K6: =Products2!I6*Prices2!D$10 -> 0 | L6: =Products2!J6*Prices2!E$10 -> 99.99 | M6: =Products2!K6*Prices2!F$10 -> 0 | N6: =Products2!L6*Prices2!G$10 -> 0 | O6: =Products2!M6*Prices2!H$10 -> 0 | P6: =Products2!N6*Prices2!I$10 -> 0 | ... AJ6: =Products2!AH6*Prices2!AC$10 -> 0 | AK6: =SUM(I6:AJ6) -> 102.9275 | AL6: =AK6-I6 -> 102.9275 | AN6: 5 | AO6: 1700 | AP6: 1689 | AQ6: 102.9275 | AS6: 1689 | AT6: 331.668 | BE6: 1740 | BF6: 157 | BG6: 1816.855 | BH6: 1475.665 | BI6: 2158.046 | BM6: 1689 | BN6: 102.93
A7: INV2446 | B7: 1 | C7: 1689 | D7: 1700 | E7: 2 | F7: 1700 | H7: 1 | I7: =Products2!G7*Prices2!B$10 -> 112.75 | J7: =Products2!H7*Prices2!C$10 -> 95.5625 | K7: =Products2!I7*Prices2!D$10 -> 31.625 | L7: =Products2!J7*Prices2!E$10 -> 202 | M7: =Products2!K7*Prices2!F$10 -> 6.5 | N7: =Products2!L7*Prices2!G$10 -> 0 | O7: =Products2!M7*Prices2!H$10 -> 0 | P7: =Products2!N7*Prices2!I$10 -> 0 | ... AJ7: =Products2!AH7*Prices2!AC$10 -> 0 | AK7: =SUM(I7:AJ7) -> 482.4375 | AL7: =AK7-I7 -> 369.6875 | AN7: 6 | AO7: 1700 | AP7: 1689 | AQ7: 482.4375 | AS7: 1690 | AT7: 474.63 | BE7: 1750 | BF7: 122 | BG7: 2084.04 | BH7: 1679.319 | BI7: 2488.761 | BM7: 1689 | BN7: 482.44
A8: INV2447 | B8: 1 | C8: 1689 | D8: 1700 | E8: 2 | F8: 1700 | H8: 1 | I8: =Products2!G8*Prices2!B$10 -> 112.75 | J8: =Products2!H8*Prices2!C$10 -> 278 | K8: =Products2!I8*Prices2!D$10 -> 47.4375 | L8: =Products2!J8*Prices2!E$10 -> 101 | M8: =Products2!K8*Prices2!F$10 -> 6.5 | N8: =Products2!L8*Prices2!G$10 -> 0 | O8: =Products2!M8*Prices2!H$10 -> 0 | P8: =Products2!N8*Prices2!I$10 -> 0 | ... AJ8: =Products2!AH8*Prices2!AC$10 -> 0 | AK8: =SUM(I8:AJ8) -> 579.6875 | AL8: =AK8-I8 -> 466.9375 | AN8: 7 | AO8: 1700 | AP8: 1689 | AQ8: 579.6875 | AS8: 1691 | AT8: 0 | BE8: 1760 | BF8: 157 | BG8: 1520.238 | BH8: 1216.225 | BI8: 1824.252 | BM8: 1689 | BN8: 579.69
A9: INV2448 | B9: 1 | C9: 1689 | D9: 1700 | E9: 1 | F9: 1700 | H9: 1 | I9: =Products2!G9*Prices2!B$10 -> 0 | J9: =Products2!H9*Prices2!C$10 -> 60.8125 | K9: =Products2!I9*Prices2!D$10 -> 0 | L9: =Products2!J9*Prices2!E$10 -> 0 | M9: =Products2!K9*Prices2!F$10 -> 6.5 | N9: =Products2!L9*Prices2!G$10 -> 0 | O9: =Products2!M9*Prices2!H$10 -> 0 | P9: =Products2!N9*Prices2!I$10 -> 0 | ... AJ9: =Products2!AH9*Prices2!AC$10 -> 0 | AK9: =SUM(I9:AJ9) -> 101.3125 | AL9: =AK9-I9 -> 101.3125 | AN9: 8 | AO9: 1700 | AP9: 1689 | AQ9: 101.3125 | AS9: 1692 | AT9: 161.363 | BE9: 1770 | BF9: 245 | BG9: 1556.942 | BH9: 1307.112 | BI9: 1806.771 | BM9: 1689 | BN9: 101.31
A10: INV2449 | B10: 1 | C10: 1689 | D10: 1700 | E10: 1 | F10: 1700 | H10: 1 | I10: =Products2!G10*Prices2!B$10 -> 0 | J10: =Products2!H10*Prices2!C$10 -> 347.5 | K10: =Products2!I10*Prices2!D$10 -> 31.625 | L10: =Products2!J10*Prices2!E$10 -> 0 | M10: =Products2!K10*Prices2!F$10 -> 6.5 | N10: =Products2!L10*Prices2!G$10 -> 0 | O10: =Products2!M10*Prices2!H$10 -> 0 | P10: =Products2!N10*Prices2!I$10 -> 0 | ... AJ10: =Products2!AH10*Prices2!AC$10 -> 0 | AK10: =SUM(I10:AJ10) -> 419.625 | AL10: =AK10-I10 -> 419.625 | AN10: 9 | AO10: 1700 | AP10: 1689 | AQ10: 419.625 | AS10: 1693 | AT10: 1762.25 | BE10: 1780 | BF10: 290 | BG10: 1971.839 | BH10: 1643.064 | BI10: 2300.614 | BM10: 1689 | BN10: 419.63
A11: INV2450 | B11: 1 | C11: 1689 | D11: 1700 | E11: 1 | F11: 1700 | H11: 1 | I11: =Products2!G11*Prices2!B$10 -> 0 | J11: =Products2!H11*Prices2!C$10 -> 260.625 | K11: =Products2!I11*Prices2!D$10 -> 47.4375 | L11: =Products2!J11*Prices2!E$10 -> 252.5 | M11: =Products2!K11*Prices2!F$10 -> 6.5 | N11: =Products2!L11*Prices2!G$10 -> 0 | O11: =Products2!M11*Prices2!H$10 -> 0 | P11: =Products2!N11*Prices2!I$10 -> 0 | ... AJ11: =Products2!AH11*Prices2!AC$10 -> 0 | AK11: =SUM(I11:AJ11) -> 601.0625 | AL11: =AK11-I11 -> 601.0625 | AN11: 10 | AO11: 1700 | AP11: 1689 | AQ11: 601.0625 | AS11: 1694 | AT11: 1108.71 | BE11: 1790 | BF11: 362 | BG11: 1978.699 | BH11: 1696.183 | BI11: 2261.215 | BM11: 1689 | BN11: 601.06
A12: INV2451 | B12: 1 | C12: 1689 | D12: 1700 | E12: 1 | F12: 1700 | H12: 1 | I12: =Products2!G12*Prices2!B$10 -> 0 | J12: =Products2!H12*Prices2!C$10 -> 112.9375 | K12: =Products2!I12*Prices2!D$10 -> 31.625 | L12: =Products2!J12*Prices2!E$10 -> 0 | M12: =Products2!K12*Prices2!F$10 -> 6.5 | N12: =Products2!L12*Prices2!G$10 -> 0 | O12: =Products2!M12*Prices2!H$10 -> 0 | P12: =Products2!N12*Prices2!I$10 -> 0 | ... AJ12: =Products2!AH12*Prices2!AC$10 -> 0 | AK12: =SUM(I12:AJ12) -> 185.0625 | AL12: =AK12-I12 -> 185.0625 | AN12: 11 | AO12: 1700 | AP12: 1689 | AQ12: 185.0625 | AS12: 1695 | AT12: 844.51 | BE12: 1800 | BF12: 414 | BG12: 1633.469 | BH12: 1442.306 | BI12: 1824.633 | BM12: 1689 | BN12: 185.06
A13: INV2452 | B13: 1 | C13: 1689 | D13: 1700 | E13: 1 | F13: 1700 | H13: 1 | I13: =Products2!G13*Prices2!B$10 -> 0 | J13: =Products2!H13*Prices2!C$10 -> 147.6875 | K13: =Products2!I13*Prices2!D$10 -> 0 | L13: =Products2!J13*Prices2!E$10 -> 20.2 | M13: =Products2!K13*Prices2!F$10 -> 6.5 | N13: =Products2!L13*Prices2!G$10 -> 0 | O13: =Products2!M13*Prices2!H$10 -> 0 | P13: =Products2!N13*Prices2!I$10 -> 2.375 | ... AJ13: =Products2!AH13*Prices2!AC$10 -> 0 | AK13: =SUM(I13:AJ13) -> 181.21562 | AL13: =AK13-I13 -> 181.21562 | AN13: 12 | AO13: 1700 | AP13: 1689 | AQ13: 181.21562 | AS13: 1696 | AT13: 1030.89 | BM13: 1689 | BN13: 181.22
A14: INV2453 | B14: 1 | C14: 1690 | D14: 1700 | E14: 2 | F14: 1700 | H14: 1 | I14: =Products2!G14*Prices2!B$10 -> 225.5 | J14: =Products2!H14*Prices2!C$10 -> 0 | K14: =Products2!I14*Prices2!D$10 -> 0 | L14: =Products2!J14*Prices2!E$10 -> 244.42 | M14: =Products2!K14*Prices2!F$10 -> 0 | N14: =Products2!L14*Prices2!G$10 -> 0 | O14: =Products2!M14*Prices2!H$10 -> 0 | P14: =Products2!N14*Prices2!I$10 -> 1.5833333 | ... AJ14: =Products2!AH14*Prices2!AC$10 -> 0 | AK14: =SUM(I14:AJ14) -> 474.62833 | AL14: =AK14-I14 -> 249.12833 | AN14: 13 | AO14: 1700 | AP14: 1690 | AQ14: 474.62833 | AS14: 1697 | AT14: 456.451 | BM14: 1690 | BN14: 474.63
A15: INV0083 | B15: 1 | C15: 1691 | D15: 1700 | E15: 1 | F15: 1700 | H15: 0 | I15: =Products2!G15*Prices2!B$10 -> 0 | J15: =Products2!H15*Prices2!C$10 -> 0 | K15: =Products2!I15*Prices2!D$10 -> 0 | L15: =Products2!J15*Prices2!E$10 -> 0 | M15: =Products2!K15*Prices2!F$10 -> 0 | N15: =Products2!L15*Prices2!G$10 -> 0 | O15: =Products2!M15*Prices2!H$10 -> 0 | P15: =Products2!N15*Prices2!I$10 -> 0 | ... AJ15: =Products2!AH15*Prices2!AC$10 -> 0 | AK15: =SUM(I15:AJ15) -> 0 | AL15: =AK15-I15 -> 0 | AN15: 14 | AO15: 1700 | AP15: 1691 | AQ15: 0 | AS15: 1698 | AT15: 1215.98 | BM15: 1692 | BN15: 151.5
A16: INV0023 | B16: 1 | C16: 1692 | D16: 1700 | E16: 1 | F16: 1700 | H16: 0 | I16: =Products2!G16*Prices2!B$10 -> 0 | J16: =Products2!H16*Prices2!C$10 -> 0 | K16: =Products2!I16*Prices2!D$10 -> 0 | L16: =Products2!J16*Prices2!E$10 -> 151.5 | M16: =Products2!K16*Prices2!F$10 -> 0 | N16: =Products2!L16*Prices2!G$10 -> 0 | O16: =Products2!M16*Prices2!H$10 -> 0 | P16: =Products2!N16*Prices2!I$10 -> 0 | ... AJ16: =Products2!AH16*Prices2!AC$10 -> 0 | AK16: =SUM(I16:AJ16) -> 151.5 | AL16: =AK16-I16 -> 151.5 | AN16: 15 | AO16: 1700 | AP16: 1692 | AQ16: 151.5 | AS16: 1699 | AT16: 990.618 | BM16: 1692 | BN16: 332.59
A17: INV0034 | B17: 1 | C17: 1692 | D17: 1700 | E17: 2 | F17: 1700 | H17: 1 | I17: =Products2!G17*Prices2!B$10 -> 225.5 | J17: =Products2!H17*Prices2!C$10 -> 34.75 | K17: =Products2!I17*Prices2!D$10 -> 15.8125 | L17: =Products2!J17*Prices2!E$10 -> 0 | M17: =Products2!K17*Prices2!F$10 -> 0 | N17: =Products2!L17*Prices2!G$10 -> 0 | O17: =Products2!M17*Prices2!H$10 -> 0 | P17: =Products2!N17*Prices2!I$10 -> 2.375 | ... AJ17: =Products2!AH17*Prices2!AC$10 -> 0 | AK17: =SUM(I17:AJ17) -> 332.59375 | AL17: =AK17-I17 -> 107.09375 | AN17: 16 | AO17: 1700 | AP17: 1692 | AQ17: 332.59375 | AS17: 1700 | AT17: 552.331 | BM17: 1693 | BN17: 435.18
A18: INV0082 | B18: 1 | C18: 1692 | D18: 1700 | E18: 1 | F18: 1700 | H18: 0 | I18: =Products2!G18*Prices2!B$10 -> 0 | J18: =Products2!H18*Prices2!C$10 -> 0 | K18: =Products2!I18*Prices2!D$10 -> 0 | L18: =Products2!J18*Prices2!E$10 -> 0 | M18: =Products2!K18*Prices2!F$10 -> 0 | N18: =Products2!L18*Prices2!G$10 -> 0 | O18: =Products2!M18*Prices2!H$10 -> 0 | P18: =Products2!N18*Prices2!I$10 -> 0 | ... AJ18: =Products2!AH18*Prices2!AC$10 -> 0 | AK18: =SUM(I18:AJ18) -> 0 | AL18: =AK18-I18 -> 0 | AN18: 17 | AO18: 1700 | AP18: 1692 | AQ18: 0 | AS18: 1701 | AT18: 2313.67 | BM18: 1693 | BN18: 4252.06
A19: INV0054 | B19: 1 | C19: 1693 | D19: 1700 | E19: 1 | F19: 1700 | G19: 1697 | H19: 0 | I19: =Products2!G19*Prices2!B$10 -> 0 | J19: =Products2!H19*Prices2!C$10 -> 34.75 | K19: =Products2!I19*Prices2!D$10 -> 47.4375 | L19: =Products2!J19*Prices2!E$10 -> 303 | M19: =Products2!K19*Prices2!F$10 -> 0 | N19: =Products2!L19*Prices2!G$10 -> 0 | O19: =Products2!M19*Prices2!H$10 -> 0 | P19: =Products2!N19*Prices2!I$10 -> 1.5833333 | ... AJ19: =Products2!AH19*Prices2!AC$10 -> 0 | AK19: =SUM(I19:AJ19) -> 435.17708 | AL19: =AK19-I19 -> 435.17708 | AN19: 18 | AO19: 1700 | AP19: 1693 | AQ19: 435.17708 | AS19: 1702 | AT19: 823.953 | AU19: =AVERAGE(AT17:AT21) -> 1364.4622 | BM19: 1693 | BN19: 599.5
A20: INV0064 | B20: 1 | C20: 1693 | D20: 1700 | E20: 3 | F20: 1700 | G20: 1697 | H20: 0 | I20: =Products2!G20*Prices2!B$10 -> 1014.75 | J20: =Products2!H20*Prices2!C$10 -> 1520.3125 | K20: =Products2!I20*Prices2!D$10 -> 0 | L20: =Products2!J20*Prices2!E$10 -> 1717 | M20: =Products2!K20*Prices2!F$10 -> 0 | N20: =Products2!L20*Prices2!G$10 -> 0 | O20: =Products2!M20*Prices2!H$10 -> 0 | P20: =Products2!N20*Prices2!I$10 -> 0 | ... AJ20: =Products2!AH20*Prices2!AC$10 -> 0 | AK20: =SUM(I20:AJ20) -> 4252.0625 | AL20: =AK20-I20 -> 3237.3125 | AN20: 19 | AO20: 1700 | AP20: 1693 | AQ20: 4252.0625 | AS20: 1703 | AT20: 2376.21 | AU20: =AVERAGE(AT18:AT22) -> 1521.868 | BM20: 1694 | BN20: 1194.48
A21: INV0075 | B21: 1 | C21: 1693 | D21: 1700 | E21: 3 | F21: 1700 | G21: 1697 | H21: 0 | I21: =Products2!G21*Prices2!B$10 -> 563.75 | J21: =Products2!H21*Prices2!C$10 -> 0 | K21: =Products2!I21*Prices2!D$10 -> 0 | L21: =Products2!J21*Prices2!E$10 -> 0 | M21: =Products2!K21*Prices2!F$10 -> 0 | N21: =Products2!L21*Prices2!G$10 -> 0 | O21: =Products2!M21*Prices2!H$10 -> 0 | P21: =Products2!N21*Prices2!I$10 -> 0 | ... AJ21: =Products2!AH21*Prices2!AC$10 -> 12.25 | AK21: =SUM(I21:AJ21) -> 599.5 | AL21: =AK21-I21 -> 35.75 | AN21: 20 | AO21: 1700 | AP21: 1693 | AQ21: 599.5 | AS21: 1704 | AT21: 756.147 | AU21: =AVERAGE(AT19:AT23) -> 1185.9146 | BM21: 1694 | BN21: 1022.94
A22: INV0002 | B22: 1 | C22: 1694 | D22: 1700 | E22: 3 | F22: 1700 | G22: 1697 | H22: 0 | I22: =Products2!G22*Prices2!B$10 -> 563.75 | J22: =Products2!H22*Prices2!C$10 -> 86.875 | K22: =Products2!I22*Prices2!D$10 -> 126.5 | L22: =Products2!J22*Prices2!E$10 -> 303 | M22: =Products2!K22*Prices2!F$10 -> 6.5 | N22: =Products2!L22*Prices2!G$10 -> 0 | O22: =Products2!M22*Prices2!H$10 -> 0 | P22: =Products2!N22*Prices2!I$10 -> 3.1666667 | ... AJ22: =Products2!AH22*Prices2!AC$10 -> 0 | AK22: =SUM(I22:AJ22) -> 1194.4792 | AL22: =AK22-I22 -> 630.72917 | AN22: 21 | AO22: 1700 | AP22: 1694 | AQ22: 1194.4792 | AS22: 1705 | AT22: 1339.36 | AU22: =AVERAGE(AT20:AT24) -> 1306.336 | BM22: 1695 | BN22: 947.04
A23: INV0003 | B23: 1 | C23: 1694 | D23: 1700 | E23: 2 | F23: 1700 | G23: 1697 | H23: 0 | I23: =Products2!G23*Prices2!B$10 -> 225.5 | J23: =Products2!H23*Prices2!C$10 -> 364.875 | K23: =Products2!I23*Prices2!D$10 -> 79.0625 | L23: =Products2!J23*Prices2!E$10 -> 353.5 | M23: =Products2!K23*Prices2!F$10 -> 0 | N23: =Products2!L23*Prices2!G$10 -> 0 | O23: =Products2!M23*Prices2!H$10 -> 0 | P23: =Products2!N23*Prices2!I$10 -> 0 | ... AJ23: =Products2!AH23*Prices2!AC$10 -> 0 | AK23: =SUM(I23:AJ23) -> 1022.9375 | AL23: =AK23-I23 -> 797.4375 | AN23: 22 | AO23: 1700 | AP23: 1694 | AQ23: 1022.9375 | AS23: 1706 | AT23: 633.903 | AU23: =AVERAGE(AT21:AT25) -> 1099.354 | BM23: 1695 | BN23: 196.75
A24: INV0004 | B24: 1 | C24: 1695 | D24: 1700 | E24: 2 | F24: 1700 | G24: 1697 | H24: 1 | I24: =Products2!G24*Prices2!B$10 -> 451 | J24: =Products2!H24*Prices2!C$10 -> 347.5 | K24: =Products2!I24*Prices2!D$10 -> 47.4375 | L24: =Products2!J24*Prices2!E$10 -> 60.6 | M24: =Products2!K24*Prices2!F$10 -> 6.5 | N24: =Products2!L24*Prices2!G$10 -> 0 | O24: =Products2!M24*Prices2!H$10 -> 0 | P24: =Products2!N24*Prices2!I$10 -> 0 | ... AJ24: =Products2!AH24*Prices2!AC$10 -> 0 | AK24: =SUM(I24:AJ24) -> 947.0375 | AL24: =AK24-I24 -> 496.0375 | AN24: 23 | AO24: 1700 | AP24: 1695 | AQ24: 947.0375 | AS24: 1707 | AT24: 1426.06 | AU24: =AVERAGE(AT22:AT26) -> 1102.1206 | BM24: 1695 | BN24: 131.69
A25: INV0005 | B25: 1 | C25: 1695 | D25: 1700 | E25: 2 | F25: 1700 | G25: 1697 | H25: 0 | I25: =Products2!G25*Prices2!B$10 -> 112.75 | J25: =Products2!H25*Prices2!C$10 -> 0 | K25: =Products2!I25*Prices2!D$10 -> 0 | L25: =Products2!J25*Prices2!E$10 -> 0 | M25: =Products2!K25*Prices2!F$10 -> 0 | N25: =Products2!L25*Prices2!G$10 -> 0 | O25: =Products2!M25*Prices2!H$10 -> 0 | P25: =Products2!N25*Prices2!I$10 -> 0 | ... AJ25: =Products2!AH25*Prices2!AC$10 -> 0 | AK25: =SUM(I25:AJ25) -> 196.75 | AL25: =AK25-I25 -> 84 | AN25: 24 | AO25: 1700 | AP25: 1695 | AQ25: 196.75 | AS25: 1708 | AT25: 1341.3 | AU25: =AVERAGE(AT23:AT27) -> 1358.7206 | BM25: 1695 | BN25: 2102.56
A26: INV0006 | B26: 1 | C26: 1695 | D26: 1700 | E26: 2 | F26: 1700 | G26: 1697 | H26: 0 | I26: =Products2!G26*Prices2!B$10 -> 112.75 | J26: =Products2!H26*Prices2!C$10 -> 0 | K26: =Products2!I26*Prices2!D$10 -> 15.8125 | L26: =Products2!J26*Prices2!E$10 -> 0 | M26: =Products2!K26*Prices2!F$10 -> 0 | N26: =Products2!L26*Prices2!G$10 -> 0 | O26: =Products2!M26*Prices2!H$10 -> 0 | P26: =Products2!N26*Prices2!I$10 -> 0 | ... AJ26: =Products2!AH26*Prices2!AC$10 -> 0 | AK26: =SUM(I26:AJ26) -> 131.6875 | AL26: =AK26-I26 -> 18.9375 | AN26: 25 | AO26: 1700 | AP26: 1695 | AQ26: 131.6875 | AS26: 1709 | AT26: 769.98 | AU26: =AVERAGE(AT24:AT28) -> 1395.37 | BM26: 1696 | BN26: 302.58
A27: INV0007 | B27: 1 | C27: 1695 | D27: 1700 | E27: 3 | F27: 1700 | G27: 1697 | H27: 1 | I27: =Products2!G27*Prices2!B$10 -> 1014.75 | J27: =Products2!H27*Prices2!C$10 -> 434.375 | K27: =Products2!I27*Prices2!D$10 -> 47.4375 | L27: =Products2!J27*Prices2!E$10 -> 606 | M27: =Products2!K27*Prices2!F$10 -> 0 | N27: =Products2!L27*Prices2!G$10 -> 0 | O27: =Products2!M27*Prices2!H$10 -> 0 | P27: =Products2!N27*Prices2!I$10 -> 0 | ... AJ27: =Products2!AH27*Prices2!AC$10 -> 0 | AK27: =SUM(I27:AJ27) -> 2102.5625 | AL27: =AK27-I27 -> 1087.8125 | AN27: 26 | AO27: 1700 | AP27: 1695 | AQ27: 2102.5625 | AS27: 1710 | AT27: 2622.36 | AU27: =AVERAGE(AT25:AT29) -> 1345.6 | BM27: 1696 | BN27: 344.38
A28: INV0008 | B28: 1 | C28: 1696 | D28: 1700 | E28: 2 | F28: 1700 | G28: 1697 | H28: 1 | I28: =Products2!G28*Prices2!B$10 -> 225.5 | J28: =Products2!H28*Prices2!C$10 -> 69.5 | K28: =Products2!I28*Prices2!D$10 -> 0 | L28: =Products2!J28*Prices2!E$10 -> 0 | M28: =Products2!K28*Prices2!F$10 -> 0 | N28: =Products2!L28*Prices2!G$10 -> 0 | O28: =Products2!M28*Prices2!H$10 -> 0 | P28: =Products2!N28*Prices2!I$10 -> 0 | ... AJ28: =Products2!AH28*Prices2!AC$10 -> 0 | AK28: =SUM(I28:AJ28) -> 302.57812 | AL28: =AK28-I28 -> 77.078125 | AN28: 27 | AO28: 1700 | AP28: 1696 | AQ28: 302.57812 | AS28: 1711 | AT28: 817.15 | AU28: =AVERAGE(AT26:AT30) -> 1384.166 | BM28: 1696 | BN28: 1825.06
A29: INV0009 | B29: 1 | C29: 1696 | D29: 1700 | E29: 1 | F29: 1700 | G29: 1697 | H29: 1 | I29: =Products2!G29*Prices2!B$10 -> 0 | J29: =Products2!H29*Prices2!C$10 -> 312.75 | K29: =Products2!I29*Prices2!D$10 -> 31.625 | L29: =Products2!J29*Prices2!E$10 -> 0 | M29: =Products2!K29*Prices2!F$10 -> 0 | N29: =Products2!L29*Prices2!G$10 -> 0 | O29: =Products2!M29*Prices2!H$10 -> 0 | P29: =Products2!N29*Prices2!I$10 -> 0 | ... AJ29: =Products2!AH29*Prices2!AC$10 -> 0 | AK29: =SUM(I29:AJ29) -> 344.375 | AL29: =AK29-I29 -> 344.375 | AN29: 28 | AO29: 1700 | AP29: 1696 | AQ29: 344.375 | AS29: 1712 | AT29: 1177.21 | AU29: =AVERAGE(AT27:AT31) -> 1419.0046 | BM29: 1696 | BN29: 738.02
A30: INV0010 | B30: 1 | C30: 1696 | D30: 1700 | E30: 2 | F30: 1700 | G30: 1697 | H30: 1 | I30: =Products2!G30*Prices2!B$10 -> 451 | J30: =Products2!H30*Prices2!C$10 -> 1042.5 | K30: =Products2!I30*Prices2!D$10 -> 79.0625 | L30: =Products2!J30*Prices2!E$10 -> 252.5 | M30: =Products2!K30*Prices2!F$10 -> 0 | N30: =Products2!L30*Prices2!G$10 -> 0 | O30: =Products2!M30*Prices2!H$10 -> 0 | P30: =Products2!N30*Prices2!I$10 -> 0 | ... AJ30: =Products2!AH30*Prices2!AC$10 -> 0 | AK30: =SUM(I30:AJ30) -> 1825.0625 | AL30: =AK30-I30 -> 1374.0625 | AN30: 29 | AO30: 1700 | AP30: 1696 | AQ30: 1825.0625 | AS30: 1713 | AT30: 1534.13 | AU30: =AVERAGE(AT28:AT32) -> 1017.3814 | BM30: 1696 | BN30: 3243.13
... A115: INV0799 | B115: 1 | C115: 1708 | D115: 1710 | E115: 3 | F115: 1720 | G115: 1712 | H115: 1 | I115: =Products2!G115*Prices2!B$10 -> 789.25 | J115: =Products2!H115*Prices2!C$10 -> 356.1875 | K115: =Products2!I115*Prices2!D$10 -> 79.0625 | L115: =Products2!J115*Prices2!E$10 -> 303 | M115: =Products2!K115*Prices2!F$10 -> 6.5 | N115: =Products2!L115*Prices2!G$10 -> 0 | O115: =Products2!M115*Prices2!H$10 -> 0 | P115: =Products2!N115*Prices2!I$10 -> 1.5833333 | ... AJ115: =Products2!AH115*Prices2!AC$10 -> 0 | AK115: =SUM(I115:AJ115) -> 1576.9896 | AL115: =AK115-I115 -> 787.73958 | AN115: 114 | AO115: 1710 | AP115: 1708 | AQ115: 1576.9896 | AS115: 1798 | AT115: 1913.22 | AU115: =AVERAGE(AT113:AT117) -> 1470.804 | BM115: 1708 | BN115: 1042.97
A116: INV0800 | B116: 1 | C116: 1708 | D116: 1710 | E116: 4 | F116: 1720 | G116: 1712 | H116: 1 | I116: =Products2!G116*Prices2!B$10 -> 3382.5 | J116: =Products2!H116*Prices2!C$10 -> 860.0625 | K116: =Products2!I116*Prices2!D$10 -> 158.125 | L116: =Products2!J116*Prices2!E$10 -> 623.17 | M116: =Products2!K116*Prices2!F$10 -> 6.5 | N116: =Products2!L116*Prices2!G$10 -> 0 | O116: =Products2!M116*Prices2!H$10 -> 0 | P116: =Products2!N116*Prices2!I$10 -> 3.1666667 | ... AJ116: =Products2!AH116*Prices2!AC$10 -> 0 | AK116: =SUM(I116:AJ116) -> 5121.9929 | AL116: =AK116-I116 -> 1739.4929 | AN116: 115 | AO116: 1710 | AP116: 1708 | AQ116: 5121.9929 | AS116: 1799 | AT116: 1013.54 | BM116: 1708 | BN116: 3883.25
A117: INV0801 | B117: 1 | C117: 1708 | D117: 1710 | E117: 2 | F117: 1720 | G117: 1712 | H117: 0 | I117: =Products2!G117*Prices2!B$10 -> 225.5 | J117: =Products2!H117*Prices2!C$10 -> 0 | K117: =Products2!I117*Prices2!D$10 -> 15.8125 | L117: =Products2!J117*Prices2!E$10 -> 0 | M117: =Products2!K117*Prices2!F$10 -> 0 | N117: =Products2!L117*Prices2!G$10 -> 0 | O117: =Products2!M117*Prices2!H$10 -> 0 | P117: =Products2!N117*Prices2!I$10 -> 2.375 | ... AJ117: =Products2!AH117*Prices2!AC$10 -> 0 | AK117: =SUM(I117:AJ117) -> 280.5625 | AL117: =AK117-I117 -> 55.0625 | AN117: 116 | AO117: 1710 | AP117: 1708 | AQ117: 280.5625 | AS117: 1800 | AT117: 1102.49 | BM117: 1708 | BN117: 358.9
A118: INV0802 | B118: 1 | C118: 1708 | D118: 1710 | E118: 1 | F118: 1720 | G118: 1712 | H118: 1 | I118: =Products2!G118*Prices2!B$10 -> 0 | J118: =Products2!H118*Prices2!C$10 -> 538.625 | K118: =Products2!I118*Prices2!D$10 -> 15.8125 | L118: =Products2!J118*Prices2!E$10 -> 474.7 | M118: =Products2!K118*Prices2!F$10 -> 6.5 | N118: =Products2!L118*Prices2!G$10 -> 0 | O118: =Products2!M118*Prices2!H$10 -> 0 | P118: =Products2!N118*Prices2!I$10 -> 1.5833333 | ... AJ118: =Products2!AH118*Prices2!AC$10 -> 0 | AK118: =SUM(I118:AJ118) -> 1111.8146 | AL118: =AK118-I118 -> 1111.8146 | AN118: 117 | AO118: 1710 | AP118: 1708 | AQ118: 1111.8146 | AS118: 1801 | AT118: 1838.87 | BM118: 1708 | BN118: 1918.78
A119: INV0807 | B119: 1 | C119: 1708 | D119: 1710 | E119: 2 | F119: 1720 | G119: 1712 | H119: 1 | I119: =Products2!G119*Prices2!B$10 -> 112.75 | J119: =Products2!H119*Prices2!C$10 -> 338.8125 | K119: =Products2!I119*Prices2!D$10 -> 63.25 | L119: =Products2!J119*Prices2!E$10 -> 298.96 | M119: =Products2!K119*Prices2!F$10 -> 6.5 | N119: =Products2!L119*Prices2!G$10 -> 0 | O119: =Products2!M119*Prices2!H$10 -> 0 | P119: =Products2!N119*Prices2!I$10 -> 1.5833333 | ... AJ119: =Products2!AH119*Prices2!AC$10 -> 0 | AK119: =SUM(I119:AJ119) -> 865.98083 | AL119: =AK119-I119 -> 753.23083 | AN119: 118 | AO119: 1710 | AP119: 1708 | AQ119: 865.98083 | AS119: 1802 | AT119: 1483.78 | BM119: 1708 | BN119: 577.45
A120: INV0808 | B120: 1 | C120: 1708 | D120: 1710 | E120: 1 | F120: 1720 | G120: 1712 | H120: 1 | I120: =Products2!G120*Prices2!B$10 -> 0 | J120: =Products2!H120*Prices2!C$10 -> 112.9375 | K120: =Products2!I120*Prices2!D$10 -> 0 | L120: =Products2!J120*Prices2!E$10 -> 20.2 | M120: =Products2!K120*Prices2!F$10 -> 6.5 | N120: =Products2!L120*Prices2!G$10 -> 0 | O120: =Products2!M120*Prices2!H$10 -> 0 | P120: =Products2!N120*Prices2!I$10 -> 0.79166667 | ... AJ120: =Products2!AH120*Prices2!AC$10 -> 0 | AK120: =SUM(I120:AJ120) -> 178.96042 | AL120: =AK120-I120 -> 178.96042 | AN120: 119 | AO120: 1710 | AP120: 1708 | AQ120: 178.96042 | AS120: 1803 | AT120: 1053.4 | BM120: 1708 | BN120: 1477.37
A121: INV0809 | B121: 1 | C121: 1708 | D121: 1710 | E121: 1 | F121: 1720 | G121: 1712 | H121: 1 | I121: =Products2!G121*Prices2!B$10 -> 0 | J121: =Products2!H121*Prices2!C$10 -> 312.75 | K121: =Products2!I121*Prices2!D$10 -> 79.0625 | L121: =Products2!J121*Prices2!E$10 -> 606 | M121: =Products2!K121*Prices2!F$10 -> 3.25 | N121: =Products2!L121*Prices2!G$10 -> 0 | O121: =Products2!M121*Prices2!H$10 -> 0 | P121: =Products2!N121*Prices2!I$10 -> 1.5833333 | ... AJ121: =Products2!AH121*Prices2!AC$10 -> 0 | AK121: =SUM(I121:AJ121) -> 1042.974 | AL121: =AK121-I121 -> 1042.974 | AN121: 120 | AO121: 1710 | AP121: 1708 | AQ121: 1042.974 | AS121: 1804 | AT121: 1022.66 | BM121: 1708 | BN121: 6.39
A122: INV0810 | B122: 1 | C122: 1708 | D122: 1710 | E122: 3 | F122: 1720 | G122: 1712 | H122: 1 | I122: =Products2!G122*Prices2!B$10 -> 1353 | J122: =Products2!H122*Prices2!C$10 -> 1980.75 | K122: =Products2!I122*Prices2!D$10 -> 284.625 | L122: =Products2!J122*Prices2!E$10 -> 134.33 | M122: =Products2!K122*Prices2!F$10 -> 13 | N122: =Products2!L122*Prices2!G$10 -> 0 | O122: =Products2!M122*Prices2!H$10 -> 0 | P122: =Products2!N122*Prices2!I$10 -> 3.1666667 | ... AJ122: =Products2!AH122*Prices2!AC$10 -> 0 | AK122: =SUM(I122:AJ122) -> 3883.2467 | AL122: =AK122-I122 -> 2530.2467 | AN122: 121 | AO122: 1710 | AP122: 1708 | AQ122: 3883.2467 | AS122: 1805 | AT122: 863.516 | BM122: 1709 | BN122: 244.09
A123: INV0811 | B123: 1 | C123: 1708 | D123: 1710 | E123: 2 | F123: 1720 | G123: 1712 | H123: 0 | I123: =Products2!G123*Prices2!B$10 -> 338.25 | J123: =Products2!H123*Prices2!C$10 -> 0 | K123: =Products2!I123*Prices2!D$10 -> 0 | L123: =Products2!J123*Prices2!E$10 -> 0 | M123: =Products2!K123*Prices2!F$10 -> 0 | N123: =Products2!L123*Prices2!G$10 -> 0 | O123: =Products2!M123*Prices2!H$10 -> 0 | P123: =Products2!N123*Prices2!I$10 -> 1.5833333 | ... AJ123: =Products2!AH123*Prices2!AC$10 -> 0 | AK123: =SUM(I123:AJ123) -> 358.89583 | AL123: =AK123-I123 -> 20.645833 | AN123: 122 | AO123: 1710 | AP123: 1708 | AQ123: 358.89583 | AS123: 1806 | AT123: 802.285 | BM123: 1709 | BN123: 36.22
A124: INV2347 | B124: 1 | C124: 1708 | D124: 1710 | E124: 2 | F124: 1720 | G124: 1712 | H124: 0 | I124: =Products2!G124*Prices2!B$10 -> 451 | J124: =Products2!H124*Prices2!C$10 -> 712.375 | K124: =Products2!I124*Prices2!D$10 -> 0 | L124: =Products2!J124*Prices2!E$10 -> 696.9 | M124: =Products2!K124*Prices2!F$10 -> 13 | N124: =Products2!L124*Prices2!G$10 -> 0 | O124: =Products2!M124*Prices2!H$10 -> 0 | P124: =Products2!N124*Prices2!I$10 -> 4.75 | ... AJ124: =Products2!AH124*Prices2!AC$10 -> 0 | AK124: =SUM(I124:AJ124) -> 1918.775 | AL124: =AK124-I124 -> 1467.775 | AN124: 123 | AO124: 1710 | AP124: 1708 | AQ124: 1918.775 | BM124: 1709 | BN124: 8.31
...

Sheet Predictions
A1: date | B1: pwealth | D1: decade | E1: pwealth | G1: decade | H1: N | I1: sum | J1: mean | K1: sd | L1: min | M1: max | N1: p10 | O1: p25 | P1: p50 | Q1: p75 | R1: p90
A2: 1673 | B2: 263.2659 | D2: 1700 | E2: 1211.218 | G2: 1700 | H2: 71 | I2: 85996.46 | J2: 1211.218 | K2: 1784.215 | L2: 0 | M2: 8653.18 | N2: 87.82177 | O2: 164.9646 | P2: 577.8901 | Q2: 1201.696 | R2: 3712.283
A3: 1685 | B3: 3712.283 | D3: 1710 | E3: 2496.303 | G3: 1710 | H3: 77 | I3: 192215.3 | J3: 2496.303 | K3: 3379.354 | L3: 0 | M3: 21958.66 | N3: 69.87946 | O3: 348.2229 | P3: 1436.7 | Q3: 3602.23 | R3: 6150.545
A4: 1687 | B4: 200.2832 | D4: 1720 | E4: 1894.416 | G4: 1720 | H4: 198 | I4: 375094.3 | J4: 1894.416 | K4: 2415.84 | L4: 0 | M4: 15123.41 | N4: 27.97614 | O4: 413.0846 | P4: 1049.77 | Q4: 2524.959 | R4: 5124.979
A5: 1688 | B5: 1201.696 | D5: 1730 | E5: 2229.125 | G5: 1730 | H5: 135 | I5: 300931.9 | J5: 2229.125 | K5: 2679.571 | L5: 0 | M5: 21305.2 | N5: 260.4011 | O5: 569.4227 | P5: 1342.647 | Q5: 3020.812 | R5: 5097.789
A6: 1689 | B6: 116.0665 | D6: 1740 | E6: 3066.329 | G6: 1740 | H6: 157 | I6: 481413.6 | J6: 3066.329 | K6: 3393.565 | L6: 0 | M6: 16769.44 | N6: 130.2005 | O6: 832.1911 | P6: 2083.738 | Q6: 3842.918 | R6: 7397.661
A7: 1689 | B7: 577.8901 | D7: 1750 | E7: 3491.625 | G7: 1750 | H7: 122 | I7: 425978.3 | J7: 3491.625 | K7: 3634.987 | L7: 0 | M7: 20788.28 | N7: 390.6017 | O7: 972.5552 | P7: 2258.019 | Q7: 4670.781 | R7: 7373.064
A8: 1689 | B8: 891.3402 | D8: 1760 | E8: 2910.731 | G8: 1760 | H8: 157 | I8: 456984.8 | J8: 2910.731 | K8: 3223.357 | L8: 0 | M8: 21116.68 | N8: 339.1921 | O8: 910.9105 | P8: 1878.26 | Q8: 3798.216 | R8: 6196.765
A9: 1689 | B9: 141.927 | D9: 1770 | E9: 2674.841 | G9: 1770 | H9: 245 | I9: 655336.1 | J9: 2674.841 | K9: 3161.209 | L9: 0 | M9: 22462.46 | N9: 107.8375 | O9: 499.9679 | P9: 1668.791 | Q9: 3679.774 | R9: 6458.165
A10: 1689 | B10: 811.0112 | D10: 1780 | E10: 3401.5 | G10: 1780 | H10: 290 | I10: 986435.1 | J10: 3401.5 | K10: 4898.26 | L10: 0 | M10: 45943.26 | N10: 207.8871 | O10: 778.6667 | P10: 2019.82 | Q10: 4253.715 | R10: 7607.279
A11: 1689 | B11: 889.0853 | D11: 1790 | E11: 3363.354 | G11: 1790 | H11: 362 | I11: 1217534 | J11: 3363.354 | K11: 4103.793 | L11: 0 | M11: 34629.51 | N11: 180.5026 | O11: 769.1656 | P11: 2248.28 | Q11: 4525.764 | R11: 7465.501
A12: 1689 | B12: 263.5786 | D12: 1800 | E12: 2637.975 | G12: 1800 | H12: 414 | I12: 1092122 | J12: 2637.975 | K12: 3109.973 | L12: 0 | M12: 26646.06 | N12: 62.13375 | O12: 415.1093 | P12: 1615.579 | Q12: 3768.705 | R12: 6361.984
A13: 1689 | B13: 631.9924 | D13: 1806 | E13: 1792.308 | G13: 1806 | H13: 349 | I13: 625515.5 | J13: 1792.308 | K13: 2949.081 | L13: 0 | M13: 40770.91 | N13: 4.755082 | O13: 260.4011 | P13: 975.3434 | Q13: 2342.644 | R13: 4447.54
A14: 1690 | B14: 709.2662 | G14: Total | H14: 2577 | I14: 6895557 | J14: 2675.808 | K14: 3508.261 | L14: 0 | M14: 45943.26 | N14: 89.20295 | O14: 517.0643 | P14: 1523.8 | Q14: 3627.104 | R14: 6391.118
A15: 1691 | B15: 0
A16: 1692 | B16: 168.4961
A17: 1692 | B17: 616.3856
A18: 1692 | B18: 0
A19: 1693 | B19: 930.0622
A20: 1693 | B20: 6629.602
A21: 1693 | B21: 1386.106
A22: 1694 | B22: 1947.382
A23: 1694 | B23: 1505.12
A24: 1695 | B24: 1399.212
A25: 1695 | B25: 949.412
A26: 1695 | B26: 131.5817
... A2578: 1806 | B2578: 3124.813

Sheet Descriptives by decade
A1: decade | B1: N | C1: sum | D1: mean | E1: sd | F1: min | G1: max | H1: p10 | I1: p25 | J1: p50 | K1: p75 | L1: p90
A2: 1700 | B2: 71 | C2: 53910.38 | D2: 759.3011 | E2: 1198.049 | F2: 0 | G2: 5406.13 | H2: 1.58 | I2: 66.52 | J2: 284.19 | K2: 738.02 | L2: 2451.51
A3: 1710 | B3: 77 | C3: 113867 | D3: 1478.792 | E3: 2104.999 | F3: 0 | G3: 13793.9 | H3: 8.31 | I3: 136.47 | J3: 577.45 | K3: 2195.23 | L3: 3883.25
A4: 1720 | B4: 198 | C4: 219691 | D4: 1109.55 | E4: 1567.193 | F4: 0 | G4: 10793.43 | H4: 6 | I4: 145 | J4: 506.19 | K4: 1632.6 | L4: 3043.44
A5: 1730 | B5: 135 | C5: 165180.4 | D5: 1223.558 | E5: 1548.999 | F5: 0 | G5: 11225.97 | H5: 33.33 | I5: 173.54 | J5: 614.35 | K5: 2052.5 | L5: 3050.5
A6: 1740 | B6: 157 | C6: 285246.3 | D6: 1816.855 | E6: 2164.293 | F6: 0 | G6: 10096.59 | H6: 65.5 | I6: 289.06 | J6: 1088.94 | K6: 2474.25 | L6: 4910.82
A7: 1750 | B7: 122 | C7: 254252.9 | D7: 2084.04 | E7: 2257.994 | F7: 0 | G7: 12907.74 | H7: 137.08 | I7: 435.62 | J7: 1397.5 | K7: 2724.71 | L7: 4961.9
A8: 1760 | B8: 157 | C8: 238677.4 | D8: 1520.238 | E8: 1928.466 | F8: 0 | G8: 11492.21 | H8: 116.54 | I8: 381.83 | J8: 878 | K8: 1842.28 | L8: 3639.68
A9: 1770 | B9: 245 | C9: 381450.7 | D9: 1556.942 | E9: 1985.269 | F9: 0 | G9: 13640.09 | H9: 24.19 | I9: 167.52 | J9: 793.89 | K9: 2277.94 | L9: 3856.28
A10: 1780 | B10: 290 | C10: 571833.3 | D10: 1971.839 | E10: 2844.637 | F10: 0 | G10: 27521.11 | H10: 39.545 | I10: 396.56 | J10: 1073.38 | K10: 2583.91 | L10: 4776.775
A11: 1790 | B11: 362 | C11: 716289 | D11: 1978.699 | E11: 2733.326 | F11: 0 | G11: 24680.16 | H11: 43.92 | I11: 292.69 | J11: 1239.52 | K11: 2711 | L11: 4383.01
A12: 1800 | B12: 414 | C12: 676256.3 | D12: 1633.469 | E12: 1978.71 | F12: 0 | G12: 16929.85 | H12: 29.5 | I12: 234.92 | J12: 1000.03 | K12: 2383.49 | L12: 4018.17
A13: Total | B13: 2228 | C13: 3676655 | D13: 1650.204 | E13: 2225.206 | F13: 0 | G13: 27521.11 | H13: 27.8 | I13: 245.295 | J13: 886.57 | K13: 2303.035 | L13: 4027.89

Sheet Group 1
A1: inv | B1: date | C1: decade | D1: group | E1: vigade | F1: quinade | G1: slaves | H1: beesten | I1: paarden | J1: schapen | K1: ploeg | L1: koornharp | M1: schuijt | N1: emmers | O1: graaven | P1: geweer | Q1: brandewijnskeetels | R1: waagen | S1: aambeeld | T1: bankschroef | U1: balans | V1: tang | W1: stoven | X1: kadels | Y1: stoel | Z1: broek | AA1: strijkijsters | AB1: boeken | AC1: horlogie | AD1: snuijfdoos | AE1: schilderij | AF1: spiegel | AG1: vogelkooi | AH1: ring | AI1: total | AJ1: totalns
A2: INV0001 | B2: 1673 | C2: 1700 | D2: 1 | E2: 1700 | G2: 0 | H2: 34.75 | I2: 0 | J2: 0 | K2: 0 | L2: 0 | M2: 0 | N2: 0 | O2: 1.15625 | P2: 3.125 | Q2: 0 | R2: 0 | S2: 0 | T2: 0 | U2: 0 | V2: 0.75 | W2: 0 | X2: 0 | Y2: 0 | Z2: 1.3125 | AA2: 0 | AB2: 0 | AC2: 0 | AD2: 0 | AE2: 2.25 | AF2: 0 | AG2: 0 | AH2: 6.125 | AI2: 49.47 | AJ2: 49.47
A3: INV2444 | B3: 1687 | C3: 1700 | D3: 1 | E3: 1700 | G3: 0 | H3: 52.125 | I3: 0 | J3: 70.7 | K3: 0 | L3: 0 | M3: 0 | N3: 0 | O3: 0 | P3: 0 | Q3: 0 | R3: 0 | S3: 0 | T3: 0 | U3: 0 | V3: 0 | W3: 0 | X3: 0 | Y3: 0 | Z3: 0 | AA3: 0 | AB3: 0 | AC3: 0 | AD3: 0 | AE3: 0 | AF3: 0 | AG3: 0 | AH3: 0 | AI3: 122.83 | AJ3: 122.83
A4: INV2445 | B4: 1689 | C4: 1700 | D4: 1 | E4: 1700 | G4: 0 | H4: 0 | I4: 0 | J4: 99.99 | K4: 0 | L4: 0 | M4: 0 | N4: 0 | O4: 0 | P4: 0 | Q4: 0 | R4: 0 | S4: 0 | T4: 0 | U4: 0 | V4: 0 | W4: 0 | X4: 1.625 | Y4: 0 | Z4: 1.3125 | AA4: 0 | AB4: 0 | AC4: 0 | AD4: 0 | AE4: 0 | AF4: 0 | AG4: 0 | AH4: 0 | AI4: 102.93 | AJ4: 102.93
A5: INV2448 | B5: 1689 | C5: 1700 | D5: 1 | E5: 1700 | G5: 0 | H5: 60.8125 | I5: 0 | J5: 0 | K5: 6.5 | L5: 0 | M5: 0 | N5: 0 | O5: 0 | P5: 0 | Q5: 0 | R5: 34 | S5: 0 | T5: 0 | U5: 0 | V5: 0 | W5: 0 | X5: 0 | Y5: 0 | Z5: 0 | AA5: 0 | AB5: 0 | AC5: 0 | AD5: 0 | AE5: 0 | AF5: 0 | AG5: 0 | AH5: 0 | AI5: 101.31 | AJ5: 101.31
A6: INV2449 | B6: 1689 | C6: 1700 | D6: 1 | E6: 1700 | G6: 0 | H6: 347.5 | I6: 31.625 | J6: 0 | K6: 6.5 | L6: 0 | M6: 0 | N6: 0 | O6: 0 | P6: 0 | Q6: 0 | R6: 34 | S6: 0 | T6: 0 | U6: 0 | V6: 0 | W6: 0 | X6: 0 | Y6: 0 | Z6: 0 | AA6: 0 | AB6: 0 | AC6: 0 | AD6: 0 | AE6: 0 | AF6: 0 | AG6: 0 | AH6: 0 | AI6: 419.63 | AJ6: 419.63
A7: INV2450 | B7: 1689 | C7: 1700 | D7: 1 | E7: 1700 | G7: 0 | H7: 260.625 | I7: 47.4375 | J7: 252.5 | K7: 6.5 | L7: 0 | M7: 0 | N7: 0 | O7: 0 | P7: 0 | Q7: 0 | R7: 34 | S7: 0 | T7: 0 | U7: 0 | V7: 0 | W7: 0 | X7: 0 | Y7: 0 | Z7: 0 | AA7: 0 | AB7: 0 | AC7: 0 | AD7: 0 | AE7: 0 | AF7: 0 | AG7: 0 | AH7: 0 | AI7: 601.06 | AJ7: 601.06
A8: INV2451 | B8: 1689 | C8: 1700 | D8: 1 | E8: 1700 | G8: 0 | H8: 112.938 | I8: 31.625 | J8: 0 | K8: 6.5 | L8: 0 | M8: 0 | N8: 0 | O8: 0 | P8: 0 | Q8: 0 | R8: 34 | S8: 0 | T8: 0 | U8: 0 | V8: 0 | W8: 0 | X8: 0 | Y8: 0 | Z8: 0 | AA8: 0 | AB8: 0 | AC8: 0 | AD8: 0 | AE8: 0 | AF8: 0 | AG8: 0 | AH8: 0 | AI8: 185.06 | AJ8: 185.06
A9: INV2452 | B9: 1689 | C9: 1700 | D9: 1 | E9: 1700 | G9: 0 | H9: 147.688 | I9: 0 | J9: 20.2 | K9: 6.5 | L9: 0 | M9: 0 | N9: 2.375 | O9: 0.578125 | P9: 3.125 | Q9: 0 | R9: 0 | S9: 0 | T9: 0 | U9: 0 | V9: 0.75 | W9: 0 | X9: 0 | Y9: 0 | Z9: 0 | AA9: 0 | AB9: 0 | AC9: 0 | AD9: 0 | AE9: 0 | AF9: 0 | AG9: 0 | AH9: 0 | AI9: 181.22 | AJ9: 181.22
A10: INV0083 | B10: 1691 | C10: 1700 | D10: 1 | E10: 1700 | G10: 0 | H10: 0 | I10: 0 | J10: 0 | K10: 0 | L10: 0 | M10: 0 | N10: 0 | O10: 0 | P10: 0 | Q10: 0 | R10: 0 | S10: 0 | T10: 0 | U10: 0 | V10: 0 | W10: 0 | X10: 0 | Y10: 0 | Z10: 0 | AA10: 0 | AB10: 0 | AC10: 0 | AD10: 0 | AE10: 0 | AF10: 0 | AG10: 0 | AH10: 0 | AI10: 0 | AJ10: 0
A11: INV0023 | B11: 1692 | C11: 1700 | D11: 1 | E11: 1700 | G11: 0 | H11: 0 | I11: 0 | J11: 151.5 | K11: 0 | L11: 0 | M11: 0 | N11: 0 | O11: 0 | P11: 0 | Q11: 0 | R11: 0 | S11: 0 | T11: 0 | U11: 0 | V11: 0 | W11: 0 | X11: 0 | Y11: 0 | Z11: 0 | AA11: 0 | AB11: 0 | AC11: 0 | AD11: 0 | AE11: 0 | AF11: 0 | AG11: 0 | AH11: 0 | AI11: 151.5 | AJ11: 151.5
A12: INV0082 | B12: 1692 | C12: 1700 | D12: 1 | E12: 1700 | G12: 0 | H12: 0 | I12: 0 | J12: 0 | K12: 0 | L12: 0 | M12: 0 | N12: 0 | O12: 0 | P12: 0 | Q12: 0 | R12: 0 | S12: 0 | T12: 0 | U12: 0 | V12: 0 | W12: 0 | X12: 0 | Y12: 0 | Z12: 0 | AA12: 0 | AB12: 0 | AC12: 0 | AD12: 0 | AE12: 0 | AF12: 0 | AG12: 0 | AH12: 0 | AI12: 0 | AJ12: 0
A13: INV0054 | B13: 1693 | C13: 1700 | D13: 1 | E13: 1700 | F13: 1697 | G13: 0 | H13: 34.75 | I13: 47.4375 | J13: 303 | K13: 0 | L13: 0 | M13: 0 | N13: 1.58333 | O13: 1.15625 | P13: 3.125 | Q13: 0 | R13: 34 | S13: 0 | T13: 0 | U13: 0 | V13: 0 | W13: 0 | X13: 0 | Y13: 3.375 | Z13: 0 | AA13: 1 | AB13: 0 | AC13: 0 | AD13: 0 | AE13: 0 | AF13: 4.5 | AG13: 1.25 | AH13: 0 | AI13: 435.18 | AJ13: 435.18
A14: INV0009 | B14: 1696 | C14: 1700 | D14: 1 | E14: 1700 | F14: 1697 | G14: 0 | H14: 312.75 | I14: 31.625 | J14: 0 | K14: 0 | L14: 0 | M14: 0 | N14: 0 | O14: 0 | P14: 0 | Q14: 0 | R14: 0 | S14: 0 | T14: 0 | U14: 0 | V14: 0 | W14: 0 | X14: 0 | Y14: 0 | Z14: 0 | AA14: 0 | AB14: 0 | AC14: 0 | AD14: 0 | AE14: 0 | AF14: 0 | AG14: 0 | AH14: 0 | AI14: 344.38 | AJ14: 344.38
A15: INV0011 | B15: 1696 | C15: 1700 | D15: 1 | E15: 1700 | F15: 1697 | G15: 0 | H15: 304.063 | I15: 15.8125 | J15: 418.14 | K15: 0 | L15: 0 | M15: 0 | N15: 0 | O15: 0 | P15: 0 | Q15: 0 | R15: 0 | S15: 0 | T15: 0 | U15: 0 | V15: 0 | W15: 0 | X15: 0 | Y15: 0 | Z15: 0 | AA15: 0 | AB15: 0 | AC15: 0 | AD15: 0 | AE15: 0 | AF15: 0 | AG15: 0 | AH15: 0 | AI15: 738.02 | AJ15: 738.02
A16: INV0015 | B16: 1697 | C16: 1700 | D16: 1 | E16: 1700 | F16: 1697 | G16: 0 | H16: 260.625 | I16: 31.625 | J16: 101 | K16: 0 | L16: 0 | M16: 0 | N16: 0 | O16: 0 | P16: 0 | Q16: 0 | R16: 0 | S16: 0 | T16: 0 | U16: 0 | V16: 0 | W16: 0 | X16: 0 | Y16: 0 | Z16: 0 | AA16: 0 | AB16: 0 | AC16: 0 | AD16: 0 | AE16: 0 | AF16: 0 | AG16: 0 | AH16: 0 | AI16: 393.25 | AJ16: 393.25
A17: INV0019 | B17: 1697 | C17: 1700 | D17: 1 | E17: 1700 | F17: 1697 | G17: 0 | H17: 0 | I17: 0 | J17: 0 | K17: 0 | L17: 0 | M17: 0 | N17: 0.791667 | O17: 0 | P17: 3.125 | Q17: 0 | R17: 0 | S17: 0 | T17: 0 | U17: 0 | V17: 0.75 | W17: 0 | X17: 4.875 | Y17: 0 | Z17: 0 | AA17: 0 | AB17: 0 | AC17: 12.125 | AD17: 0 | AE17: 0 | AF17: 4.5 | AG17: 0 | AH17: 0 | AI17: 26.17 | AJ17: 26.17
A18: INV0020 | B18: 1697 | C18: 1700 | D18: 1 | E18: 1700 | F18: 1697 | G18: 0 | H18: 0 | I18: 15.8125 | J18: 0 | K18: 0 | L18: 0 | M18: 30 | N18: 1.58333 | O18: 0 | P18: 0 | Q18: 0 | R18: 0 | S18: 0 | T18: 0 | U18: 0 | V18: 0.75 | W18: 0 | X18: 1.625 | Y18: 3.375 | Z18: 0 | AA18: 1 | AB18: 0 | AC18: 0 | AD18: 0 | AE18: 12.375 | AF18: 0 | AG18: 0 | AH18: 0 | AI18: 66.52 | AJ18: 66.52
A19: INV0024 | B19: 1697 | C19: 1700 | D19: 1 | E19: 1700 | F19: 1697 | G19: 0 | H19: 173.75 | I19: 31.625 | J19: 0 | K19: 0 | L19: 0 | M19: 0 | N19: 0 | O19: 0 | P19: 0 | Q19: 0 | R19: 0 | S19: 0 | T19: 0 | U19: 0 | V19: 0 | W19: 0 | X19: 0 | Y19: 0 | Z19: 0 | AA19: 0 | AB19: 0 | AC19: 0 | AD19: 0 | AE19: 0 | AF19: 0 | AG19: 0 | AH19: 0 | AI19: 205.38 | AJ19: 205.38
A20: INV0025 | B20: 1697 | C20: 1700 | D20: 1 | E20: 1700 | F20: 1697 | G20: 0 | H20: 0 | I20: 0 | J20: 0 | K20: 0 | L20: 0 | M20: 0 | N20: 0 | O20: 0 | P20: 0 | Q20: 0 | R20: 0 | S20: 0 | T20: 0 | U20: 0 | V20: 0 | W20: 0 | X20: 0 | Y20: 0 | Z20: 0 | AA20: 1 | AB20: 0 | AC20: 0 | AD20: 0 | AE20: 0 | AF20: 0 | AG20: 0 | AH20: 3.0625 | AI20: 4.06 | AJ20: 4.06
A21: INV0026 | B21: 1697 | C21: 1700 | D21: 1 | E21: 1700 | F21: 1697 | G21: 0 | H21: 0 | I21: 31.625 | J21: 0 | K21: 0 | L21: 0 | M21: 0 | N21: 0 | O21: 0 | P21: 0 | Q21: 0 | R21: 0 | S21: 0 | T21: 0 | U21: 0 | V21: 0 | W21: 0 | X21: 1.625 | Y21: 3.375 | Z21: 0 | AA21: 0 | AB21: 0 | AC21: 0 | AD21: 0 | AE21: 0 | AF21: 0 | AG21: 0 | AH21: 0 | AI21: 36.63 | AJ21: 36.63
A22: INV0032 | B22: 1697 | C22: 1700 | D22: 1 | E22: 1700 | F22: 1697 | G22: 0 | H22: 286.688 | I22: 0 | J22: 0 | K22: 6.5 | L22: 0 | M22: 0 | N22: 0 | O22: 0 | P22: 0 | Q22: 0 | R22: 34 | S22: 0 | T22: 0 | U22: 0 | V22: 0 | W22: 0 | X22: 1.625 | Y22: 0 | Z22: 0 | AA22: 0 | AB22: 0 | AC22: 0 | AD22: 0 | AE22: 0 | AF22: 0 | AG22: 0 | AH22: 0 | AI22: 328.81 | AJ22: 328.81
A23: INV0031 | B23: 1698 | C23: 1700 | D23: 1 | E23: 1700 | F23: 1702 | G23: 0 | H23: 0 | I23: 47.4375 | J23: 0 | K23: 0 | L23: 0 | M23: 0 | N23: 0 | O23: 0 | P23: 0 | Q23: 0 | R23: 0 | S23: 15.375 | T23: 0 | U23: 0 | V23: 0 | W23: 0 | X23: 0 | Y23: 0 | Z23: 0 | AA23: 0 | AB23: 0 | AC23: 0 | AD23: 0 | AE23: 0 | AF23: 0 | AG23: 0 | AH23: 0 | AI23: 62.81 | AJ23: 62.81
A24: INV2454 | B24: 1698 | C24: 1700 | D24: 1 | E24: 1700 | F24: 1702 | G24: 0 | H24: 52.125 | I24: 0 | J24: 0 | K24: 6.5 | L24: 0 | M24: 0 | N24: 0 | O24: 0 | P24: 0 | Q24: 0 | R24: 34 | S24: 0 | T24: 0 | U24: 0 | V24: 0 | W24: 0 | X24: 0 | Y24: 0 | Z24: 0 | AA24: 0 | AB24: 0 | AC24: 0 | AD24: 0 | AE24: 0 | AF24: 0 | AG24: 0 | AH24: 0 | AI24: 92.63 | AJ24: 92.63
... A751: INV2571 | B751: 1802 | C751: 1806 | D751: 1 | E751: 1806 | F751: 1802 | G751: 0 | H751: 0 | I751: 0 | J751: 0 | K751: 0 | L751: 0 | M751: 0 | N751: 0 | O751: 0 | P751: 0 | Q751: 0 | R751: 0 | S751: 0 | T751: 0 | U751: 0 | V751: 0 | W751: 0 | X751: 0 | Y751: 0 | Z751: 0 | AA751: 0 | AB751: 0 | AC751: 0 | AD751: 0 | AE751: 0 | AF751: 0 | AG751: 0 | AH751: 0 | AI751: 0 | AJ751: 0
A752: INV1087 | B752: 1803 | C752: 1806 | D752: 1 | E752: 1806 | G752: 0 | H752: 0 | I752: 0 | J752: 0 | K752: 0 | L752: 0 | M752: 0 | N752: 0 | O752: 0 | P752: 0 | Q752: 0 | R752: 0 | S752: 0 | T752: 0 | U752: 0 | V752: 0 | W752: 0 | X752: 0 | Y752: 0 | Z752: 31.5 | AA752: 0 | AB752: 16.6667 | AC752: 12.125 | AD752: 4.1875 | AE752: 0 | AF752: 0 | AG752: 0 | AH752: 6.125 | AI752: 70.6 | AJ752: 70.6
A753: INV1168 | B753: 1803 | C753: 1806 | D753: 1 | E753: 1806 | G753: 0 | H753: 0 | I753: 0 | J753: 0 | K753: 0 | L753: 0 | M753: 0 | N753: 0 | O753: 0 | P753: 12.5 | Q753: 0 | R753: 0 | S753: 0 | T753: 0 | U753: 0 | V753: 0 | W753: 0 | X753: 0 | Y753: 0 | Z753: 26.25 | AA753: 0 | AB753: 3.33333 | AC753: 12.125 | AD753: 0 | AE753: 0 | AF753: 2.25 | AG753: 0 | AH753: 0 | AI753: 56.46 | AJ753: 56.46
A754: INV1198 | B754: 1803 | C754: 1806 | D754: 1 | E754: 1806 | G754: 0 | H754: 0 | I754: 0 | J754: 0 | K754: 0 | L754: 0 | M754: 0 | N754: 0 | O754: 0 | P754: 0 | Q754: 0 | R754: 0 | S754: 0 | T754: 28.5 | U754: 0 | V754: 0.75 | W754: 0 | X754: 0 | Y754: 0 | Z754: 6.5625 | AA754: 0 | AB754: 1.33333 | AC754: 12.125 | AD754: 0 | AE754: 0 | AF754: 0 | AG754: 0 | AH754: 0 | AI754: 49.27 | AJ754: 49.27
