Workbook

Sheet 1865
A1: CENSUS OF THE CAPE COLONY. - 1865
A2: VII. - OCCUPATION.
A3: TOTAL COLONY.
B4: White. | D4: Coloured. | G4: White. | I4: Coloured.
B5: M. | C5: F. | D5: M. | E5: F. | G5: M. | H5: F. | I5: M. | J5: F.
A6: AGRICULTURE | F6: Brought forward | G6: 36885 | H6: 1124 | I6: 11255 | J6: 548
A7: Farmers, Corn | B7: 9926 | C7: 57 | D7: 4470 | E7: 13
A8: " Sheep and Cattle | B8: 11746 | C8: 97 | D8: 1750 | E8: 20 | F8: LABOURERS
A9: " Wine | B9: 1272 | C9: 6 | D9: 15 | E9: 0 | F9: Agricultural | G9: 3594 | H9: 19 | I9: 40012 | J9: 1310
A10: Gardeners (Market) | B10: 263 | C10: 9 | D10: 92 | E10: 3 | F10: Porters and Messengers | G10: 158 | H10: 1 | I10: 45 | J10: 17
F11: Washermen and Women | G11: 8 | H11: 279 | I11: 28 | J11: 2177
A12: TRADE AND COMMERCE: | F12: Other | G12: 2422 | H12: 100 | I12: 18627 | J12: 520
A13: Auctioneers | B13: 64 | C13: 0 | D13: 0 | E13: 0
A14: Boarding-house-keepers (Private) | B14: 33 | C14: 37 | D14: 1 | E14: 3 | F14: DOMESTIC SERVANTS | G14: 1000 | H14: 1946 | I14: 5133 | J14: 22413
A15: Brokers | B15: 29 | C15: 0 | D15: 1 | E15: 0
A16: Butchers | B16: 252 | C16: 3 | D16: 126 | E16: 0 | F16: LITERARY, SCIENTIFIC, AND PROFESSIONAL
A17: Canteen-keepers | B17: 149 | C17: 5 | D17: 26 | E17: 3 | F17: Advocates | G17: 8 | H17: 0 | I17: 0 | J17: 0
A18: Carriers and Conveyers (including Railway Officials) | B18: 549 | C18: 1 | D18: 510 | E18: 1 | F18: Apothecaries, Chemists, and Druggists | G18: 118 | H18: 0 | I18: 0 | J18: 0
A19: Contractors | B19: 42 | C19: 0 | D19: 4 | E19: 0 | F19: Architects | G19: 13 | H19: 0 | I19: 0 | J19: 0
A20: General Agents | B20: 94 | C20: 0 | D20: 10 | E20: 4 | F20: Attorneys, Notaries, Conveyancers and Law Agents | G20: 195 | H20: 0 | I20: 2 | J20: 0
A21: Inn and Hotel-keepers | B21: 338 | C21: 35 | D21: 11 | E21: 2 | F21: Church Clerks and Sextons | G21: 13 | H21: 0 | I21: 1 | J21: 0
A22: Ironmongers | B22: 4 | C22: 0 | D22: 0 | E22: 0 | F22: Clergymen and Catechists | G22: 305 | H22: 0 | I22: 6 | J22: 0
A23: Livery-stable-keepers | B23: 9 | C23: 0 | D23: 2 | E23: 0 | F23: Engineers and Surveyors | G23: 137 | H23: 0 | I23: 2 | J23: 0
A24: Merchants, Wholesale and Retail Dealers | B24: 3947 | C24: 209 | D24: 189 | E24: 41 | F24: Medical Practitioners | G24: 143 | H24: 0 | I24: 5 | J24: 0
A25: Public Companies - Officers of | B25: 148 | C25: 0 | D25: 5 | E25: 0 | F25: Midwives | G25: 0 | H25: 46 | I25: 0 | J25: 77
F26: Priests- Jewish and Mohammedan | G26: 3 | H26: 0 | I26: 19 | J26: 0
A27: MANUFACTURES, MECHANICS, AND ARTIFICERS | F27: Students | G27: 58 | H27: 0 | I27: 0 | J27: 0
A28: Bakers | B28: 274 | C28: 4 | D28: 84 | E28: 2 | F28: Teachers | G28: 806 | H28: 463 | I28: 102 | J28: 39
A29: Basketmakers | B29: 14 | C29: 2 | D29: 32 | E29: 0 | F29: Translators | G29: 2 | H29: 0 | I29: 5 | J29: 0
A30: Blacksmiths & Mechanical Engineers | B30: 798 | C30: 0 | D30: 245 | E30: 0 | F30: Professional (not otherwise enumerated) | G30: 108 | H30: 2 | I30: 0 | J30: 0
A31: Bookbinders | B31: 32 | C31: 0 | D31: 15 | E31: 0
A32: Boot and Shoemakers | B32: 741 | C32: 1 | D32: 441 | E32: 2 | F32: INDEPENDENT PROPRIETORS | G32: 169 | H32: 22 | I32: 3 | J32: 0
A33: Brewers | B33: 29 | C33: 0 | D33: 4 | E33: 0
A34: Brickmakers | B34: 70 | C34: 0 | D34: 108 | E34: 2 | F34: MILITARY SERVICE | G34: 715 | H34: 0 | I34: 8 | J34: 0
A35: Builders, Bricklayers, Masons, &c. | B35: 1161 | C35: 0 | D35: 987 | E35: 0
A36: Carpenters, Joiners, & Cabinetmakers | B36: 1605 | C36: 0 | D36: 399 | E36: 0 | F36: NAVAL SERVICE | G36: 36 | H36: 0 | I36: 2 | J36: 0
A37: Charcoal Burners | B37: 15 | C37: 0 | D37: 5 | E37: 0
A38: Clock and Watchmakers, Jewellers, and Gold and Silversmiths | B38: 112 | C38: 0 | D38: 11 | E38: 0 | F38: MARINERS, BOATMEN, FISHERMEN, AND STEVEDORES | G38: 674 | H38: 0 | I38: 721 | J38: 0
A39: Coachbuilders, Wagonmakers, and Wheelwrights | B39: 781 | C39: 0 | D39: 224 | E39: 0
A40: Coopers | B40: 95 | C40: 0 | D40: 84 | E40: 0 | F40: CIVIL SERVICE | G40: 1142 | H40: 12 | I40: 136 | J40: 0
...

Sheet 1865 v. 1875
A1: TABLE XII. - OCCUPATIONS. - Shewing the Occupations of the Population of the Colony, according to the Censuses of March, 1865, and March, 1875, arranged in Sixty-one Sub Orders.
A2: CLASS. | B2: ORDER. | C2: SUB-ORDER. | D2: OCCUPATIONS | E2: TOTAL. | K2: EUROPEAN OR WHITE. | O2: EXCLUSIVE OF EUROPEAN OR WHITE.
E3: MARCH, 1865. | H3: MARCH, 1875. | K3: MARCH, 1865. | M3: MARCH, 1875. | O3: MARCH, 1865. | Q3: MARCH, 1875.
E4: Persons. | F4: Males. | G4: Females | H4: Persons. | I4: Males. | J4: Females | K4: Males. | L4: Females | M4: Males. | N4: Females | O4: Males. | P4: Females | Q4: Males. | R4: Females
D5: Total Population | E5: 496381 | F5: 255760 | G5: 240621 | H5: 720984 | I5: 369628 | J5: 351356 | K5: 95410 | L5: 86182 | M5: 123910 | N5: 112873 | O5: 160350 | P5: 154439 | Q5: 245718 | R5: 238483
D6: Total of Specified Occupations | E6: 187577 | F6: 140943 | G6: 46634 | H6: 400100 | I6: 213377 | J6: 186723 | K6: 57742 | L6: 12411 | M6: 78365 | N6: 62535 | O6: 83201 | P6: 34223 | Q6: 135012 | R6: 124188
A8: I. | B8: I. | C8: 1 | D8: Officers of General Government | E8: 1290 | F8: 1278 | G8: 12 | H8: 1290 | I8: 1237 | J8: 53 | K8: 1142 | L8: 12 | M8: 954 | N8: 52 | O8: 136 | P8: 0 | Q8: 283 | R8: 1
C9: 2 | D9: Officers of Local Government | E9: 0 | F9: 0 | G9: 0 | H9: 80 | I9: 80 | J9: 0 | K9: 0 | L9: 0 | M9: 65 | N9: 0 | O9: 0 | P9: 0 | Q9: 15 | R9: 0
C10: 3 | D10: Engaged in Defence | E10: 761 | F10: 761 | G10: 0 | H10: 3165 | I10: 3165 | J10: 0 | K10: 751 | L10: 0 | M10: 3952 | N10: 0 | O10: 10 | P10: 0 | Q10: 213 | R10: 0
B12: II. | C12: 1 | D12: Clergymen, Ministers, and Church Officers | E12: 347 | F12: 347 | G12: 0 | H12: 538 | I12: 481 | J12: 57 | K12: 321 | L12: 0 | M12: 396 | N12: 57 | O12: 26 | P12: 0 | Q12: 85 | R12: 0
C13: 2 | D13: Law Court Officers, Barristers, Attorneys and Law Agents and Immediate Subordinates | E13: 205 | F13: 205 | G13: 0 | H13: 216 | I13: 216 | J13: 0 | K13: 203 | L13: 0 | M13: 215 | N13: 0 | O13: 2 | P13: 0 | Q13: 1 | R13: 0
C14: 3 | D14: Physicians, Surgeons, Chemists, &c. | E14: 389 | F14: 266 | G14: 123 | H14: 542 | I14: 285 | J14: 257 | K14: 261 | L14: 46 | M14: 274 | N14: 85 | O14: 5 | P14: 77 | Q14: 11 | R14: 172
C15: 4 | D15: Literary Persons | E15: 7 | F15: 7 | G15: 0 | H15: 23 | I15: 23 | J15: 0 | K15: 2 | L15: 0 | M15: 14 | N15: 0 | O15: 5 | P15: 0 | Q15: 9 | R15: 0
C16: 5 | D16: Scientific Persons | E16: 249 | F16: 247 | G16: 2 | H16: 98 | I16: 98 | J16: 0 | K16: 245 | L16: 2 | M16: 97 | N16: 0 | O16: 2 | P16: 0 | Q16: 1 | R16: 0
C17: 6 | D17: Teachers, &c. | E17: 1410 | F17: 908 | G17: 502 | H17: 1787 | I17: 926 | J17: 861 | K17: 806 | L17: 463 | M17: 783 | N17: 815 | O17: 102 | P17: 39 | Q17: 143 | R17: 46
C18: 7 | D18: Artists | E18: 22 | F18: 22 | G18: 0 | H18: 79 | I18: 76 | J18: 3 | K18: 22 | L18: 0 | M18: 75 | N18: 3 | O18: 0 | P18: 0 | Q18: 1 | R18: 0
C19: 8 | D19: Musicians, Music Teachers | E19: 0 | F19: 0 | G19: 0 | H19: 76 | I19: 50 | J19: 26 | K19: 0 | L19: 0 | M19: 39 | N19: 26 | O19: 0 | P19: 0 | Q19: 11 | R19: 0
C20: 9 | D20: Actors, &c. | E20: 0 | F20: 0 | G20: 0 | H20: 22 | I20: 18 | J20: 4 | K20: 0 | L20: 0 | M20: 16 | N20: 4 | O20: 0 | P20: 0 | Q20: 2 | R20: 0
A22: II. | B22: III. | D22: Wives and Mistresses of Families | E22: 0 | F22: 0 | G22: 0 | H22: 51923 | I22: 0 | J22: 51923 | K22: 0 | L22: 0 | M22: 0 | N22: 16770 | O22: 0 | P22: 0 | Q22: 0 | R22: 35153
B24: IV. | C24: 1 | D24: Engaged in Board and Lodging | E24: 460 | F24: 383 | G24: 77 | H24: 933 | I24: 507 | J24: 426 | K24: 371 | L24: 72 | M24: 477 | N24: 408 | O24: 12 | P24: 5 | Q24: 30 | R24: 18
C25: 2 | D25: Engaged in Attendance | E25: 30675 | F25: 6308 | G25: 24367 | H25: 30410 | I25: 8299 | J25: 22111 | K25: 1149 | L25: 1951 | M25: 1255 | N25: 2381 | O25: 5159 | P25: 22416 | Q25: 7044 | R25: 19730
Q26: 41 | R26: 2
A27: III. | B27: V. | C27: 1 | D27: Engaged in Merchantile Pursuits | E27: 4741 | F27: 4487 | G27: 254 | H27: 3538 | I27: 3498 | J27: 40 | K27: 4282 | L27: 209 | M27: 3457 | N27: 38 | O27: 205 | P27: 45 | Q27: 160 | R27: 14
C28: 2 | D28: Other General Dealers | E28: 0 | F28: 0 | G28: 0 | H28: 3436 | I28: 2179 | J28: 257 | K28: 0 | L28: 0 | M28: 2019 | N28: 243 | O28: 0 | P28: 0 | Q28: 0 | R28: 0
B30: VI. | C30: 1 | D30: Carriers on Railways | E30: 1072 | F30: 1070 | G30: 2 | H30: 333 | I30: 329 | J30: 4 | K30: 558 | L30: 1 | M30: 309 | N30: 4 | O30: 512 | P30: 1 | Q30: 20 | R30: 4
C31: 2 | D31: Carriers on Roads | E31: 0 | F31: 0 | G31: 0 | H31: 4137 | I31: 4126 | J31: 11 | K31: 0 | L31: 0 | M31: 1476 | N31: 7 | O31: 0 | P31: 0 | Q31: 2650
C32: 3 | D32: Carriers on Seas and Rivers | E32: 1395 | F32: 1395 | G32: 0 | H32: 1921 | I32: 1909 | J32: 12 | K32: 674 | L32: 0 | M32: 1742 | N32: 11 | O32: 721 | P32: 0 | Q32: 167 | R32: 1
C33: 4 | D33: Engaged in Storage | E33: 0 | F33: 0 | G33: 0 | H33: 564 | I33: 564 | J33: 0 | K33: 0 | L33: 0 | M33: 326 | N33: 0 | O33: 0 | P33: 0 | Q33: 238
C34: 5 | D34: Messangers and Porters | E34: 221 | F34: 203 | G34: 18 | H34: 388 | I34: 387 | J34: 1 | K34: 158 | L34: 1 | M34: 177 | N34: 0 | O34: 45 | P34: 17 | Q34: 210 | R34: 1
A36: IV. | B36: VII. | C36: 1 | D36: Engaged in Agriculture Pursuits | E36: 61061 | F36: 59644 | G36: 1417 | H36: 181785 | I36: 101586 | J36: 80199 | K36: 15055 | L36: 91 | M36: 25341 | N36: 26193 | O36: 44589 | P36: 1326 | Q36: 76245 | R36: 54006
C37: 2 | D37: Engaged in Pastoral Pursuits | E37: 13613 | F37: 13496 | G37: 117 | H37: 26071 | I37: 25748 | J37: 323 | K37: 11746 | L37: 97 | M37: 8327 | N37: 192 | O37: 1750 | P37: 20 | Q37: 17421 | R37: 131
C38: 3 | D38: Engaged on Land (not cultivating or grazing) | E38: 0 | F38: 0 | G38: 0 | H38: 139 | I38: 126 | J38: 13 | K38: 0 | L38: 0 | M38: 71 | N38: 3 | O38: 0 | P38: 0 | Q38: 55 | R38: 10
C39: 4 | D39: Engaged about Animals | E39: 38 | F39: 38 | G39: 0 | H39: 1141 | I39: 1140 | J39: 1 | K39: 28 | L39: 0 | M39: 330 | N39: 1 | O39: 10 | P39: 0 | Q39: 810 | R39: 0
A41: V. | B41: VIII. | C41: 1 | D41: Engaged in Books | E41: 362 | F41: 362 | G41: 0 | H41: 415 | I41: 405 | J41: 10 | K41: 300 | L41: 0 | M41: 362 | N41: 10 | O41: 62 | P41: 0 | Q41: 43 | R41: 0
C42: 2 | D42: Engaged in Musical Instrumemts | E42: 0 | F42: 0 | G42: 0 | H42: 19 | I42: 19 | J42: 0 | K42: 0 | L42: 0 | M42: 19 | N42: 0 | O42: 0 | P42: 0 | Q42: 0 | R42: 0
C43: 3 | D43: Engaged in Prints and Pictures | E43: 0 | F43: 0 | G43: 0 | H43: 1 | I43: 1 | J43: 0 | K43: 0 | L43: 0 | M43: 1 | N43: 0 | O43: 0 | P43: 0 | Q43: 0 | R43: 0
C44: 4 | D44: Engaged in Carving and Figures | E44: 0 | F44: 0 | G44: 0 | H44: 21 | I44: 20 | J44: 1 | K44: 0 | L44: 0 | M44: 2 | N44: 1 | O44: 0 | P44: 0 | Q44: 18 | R44: 0
C45: 5 | D45: Engaged in Designs | E45: 0 | F45: 0 | G45: 0 | H45: 4 | I45: 4 | J45: 0 | K45: 0 | L45: 0 | M45: 4 | N45: 0 | O45: 0 | P45: 0 | Q45: 0 | R45: 0
C46: 6 | D46: Engaged in Watches | E46: 123 | F46: 123 | G46: 0 | H46: 90 | I46: 90 | J46: 0 | K46: 112 | L46: 0 | M46: 84 | N46: 0 | O46: 11 | P46: 0 | Q46: 6 | R46: 0
C47: 7 | D47: Engaged in Arms | E47: 44 | F47: 44 | G47: 0 | H47: 32 | I47: 32 | J47: 0 | K47: 43 | L47: 0 | M47: 32 | N47: 0 | O47: 1 | P47: 0 | Q47: 0 | R47: 0
...

Sheet 1891
A1: TABLE VII. - OCCUPATIONS. - Shewing the Occupations of the Population of the Colony, according to the Censuses of 1891
A2: CLASS. | B2: ORDER. | C2: SUB-ORDER. | D2: OCCUPATIONS | E2: EUROPEAN OR WHITE. | H2: Malay | K2: Hottentot. | N2: Fingo. | Q2: Kafir and Bechuana | T2: Mixed and Other. | W2: TOTAL.
E3: Persons. | F3: Males. | G3: Females | H3: Persons. | I3: Males. | J3: Females | K3: Persons. | L3: Males. | M3: Females | N3: Persons. | O3: Males. | P3: Females | Q3: Persons. | R3: Males. | S3: Females | T3: Persons. | U3: Males. | V3: Females | W3: Persons. | X3: Males. | Y3: Females
D5: Total Population | E5: 376987 | F5: 195956 | G5: 181031 | H5: 13907 | I5: 6713 | J5: 7194 | K5: 50388 | L5: 26248 | M5: 24140 | N5: 229680 | O5: 108566 | P5: 121114 | Q5: 608456 | R5: 306635 | S5: 301821 | T5: 247806 | U5: 123209 | V5: 124597 | W5: 1527224 | X5: 767327 | Y5: 759897 | AA5: European/White working age male population
AB6: 1891 | AC6: 18.91
A7: I. | B7: I. | C7: 1 | D7: Officers of General Government | E7: 2578 | F7: 2504 | G7: 74 | H7: 4 | I7: 4 | J7: 0 | K7: 18 | L7: 18 | M7: 0 | N7: 373 | O7: 373 | P7: 0 | Q7: 870 | R7: 867 | S7: 3 | T7: 173 | U7: 160 | V7: 13 | W7: 4016 | X7: 3926 | Y7: 90 | AA7: White collar | AB7: =F7+F8+F9+F11+F12+F13+F14+F15+F16+F17+F18+F19+F20+F24+F27+F29+F30+F31+F32+F34+F33+F41+F42+F43+F44+F45+F46+F47+F48+F49+F50+F51+F52 -> 31715 | AC7: =AB7/$AB$11*100 -> 27.926
C8: 2 | D8: Officers of Local Government | E8: 241 | F8: 240 | G8: 1 | H8: 1 | I8: 1 | J8: 0 | K8: 1 | L8: 1 | M8: 0 | N8: 1 | O8: 1 | P8: 0 | Q8: 14 | R8: 14 | S8: 0 | T8: 20 | U8: 18 | V8: 2 | W8: 278 | X8: 275 | Y8: 3 | AA8: Farmer | AB8: =F36+F37+F38+F39 -> 59509 | AC8: =AB8/$AB$11*100 -> 52.399444
C9: 3 | D9: Engaged in Defence | E9: 3207 | F9: 3207 | G9: 0 | H9: 0 | I9: 0 | J9: 0 | K9: 0 | L9: 0 | M9: 0 | N9: 0 | O9: 0 | P9: 0 | Q9: 1 | R9: 1 | S9: 0 | T9: 148 | U9: 148 | V9: 0 | W9: 3356 | X9: 3356 | Y9: 0 | AA9: Skilled/semi-skilled | AB9: =F54+F55+F56+F57+F59+F60+F61+F64+F63+F65+F67+F68+F70+F71+F72+F73+F74+F75+F76 -> 20075 | AC9: =AB9/$AB$11*100 -> 17.676634
AA10: Unskilled | AB10: =F78 -> 2269 | AC10: =AB10/$AB$11*100 -> 1.9979219
B11: II. | C11: 1 | D11: Clergymen, Ministers, and Church Officers | E11: 996 | F11: 800 | G11: 196 | H11: 19 | I11: 19 | J11: 0 | K11: 1 | L11: 1 | M11: 0 | N11: 126 | O11: 124 | P11: 2 | Q11: 108 | R11: 105 | S11: 3 | T11: 39 | U11: 34 | V11: 5 | W11: 1289 | X11: 1083 | Y11: 206 | AA11: Total working age | AB11: =SUM(AB7:AB10) -> 113568 | AC11: =AB11/$AB$11*100 -> 100
C12: 2 | D12: Law Court Officers, Barristers, Attorneys and Law Agents and Immediate Subordinates | E12: 676 | F12: 671 | G12: 5 | H12: 0 | I12: 0 | J12: 0 | K12: 0 | L12: 0 | M12: 0 | N12: 4 | O12: 4 | Q12: 7 | R12: 7 | T12: 7 | U12: 7 | W12: 694 | X12: 689 | Y12: 5
C13: 3 | D13: Physicians, Surgeons, Chemists, &c. | E13: 1159 | F13: 794 | G13: 365 | H13: 18 | I13: 1 | J13: 17 | K13: 28 | L13: 2 | M13: 26 | N13: 39 | O13: 35 | P13: 4 | Q13: 86 | R13: 64 | S13: 22 | T13: 326 | U13: 39 | V13: 287 | W13: 1656 | X13: 935 | Y13: 721
C14: 4 | D14: Literary Persons | E14: 132 | F14: 105 | G14: 27 | H14: 0 | I14: 0 | J14: 0 | K14: 0 | L14: 0 | M14: 0 | N14: 1 | O14: 1 | P14: 0 | Q14: 0 | R14: 0 | S14: 0 | T14: 2 | U14: 1 | V14: 1 | W14: 135 | X14: 107 | Y14: 28
C15: 5 | D15: Scientific Persons | E15: 13 | F15: 13 | G15: 0 | H15: 0 | I15: 0 | J15: 0 | K15: 0 | L15: 0 | M15: 0 | N15: 0 | O15: 0 | P15: 0 | Q15: 0 | R15: 0 | S15: 0 | T15: 0 | U15: 0 | V15: 0 | W15: 13 | X15: 13 | Y15: 0
C16: 6 | D16: Engineering, Surveying and Architechture | E16: 231 | F16: 230 | G16: 1 | H16: 0 | I16: 0 | J16: 0 | K16: 0 | L16: 0 | M16: 0 | N16: 2 | O16: 2 | P16: 0 | Q16: 14 | R16: 14 | T16: 2 | U16: 2 | V16: 0 | W16: 249 | X16: 248 | Y16: 1
C17: 7 | D17: Teachers, &c. | E17: 4217 | F17: 1069 | G17: 3148 | H17: 12 | I17: 8 | J17: 4 | K17: 11 | L17: 7 | M17: 4 | N17: 450 | O17: 277 | P17: 173 | Q17: 269 | R17: 179 | S17: 90 | T17: 292 | U17: 107 | V17: 185 | W17: 5251 | X17: 1647 | Y17: 3604
C18: 8 | D18: Artists | E18: 267 | F18: 210 | G18: 57 | H18: 0 | I18: 0 | J18: 0 | K18: 0 | L18: 0 | M18: 0 | N18: 0 | O18: 0 | P18: 0 | Q18: 0 | R18: 0 | S18: 0 | T18: 9 | U18: 7 | V18: 2 | W18: 276 | X18: 217 | Y18: 59
C19: 9 | D19: Musicians, Music Teachers | E19: 381 | F19: 122 | G19: 259 | H19: 2 | I19: 2 | J19: 0 | K19: 0 | L19: 0 | M19: 0 | N19: 3 | O19: 3 | Q19: 6 | R19: 3 | S19: 3 | T19: 7 | U19: 6 | V19: 1 | W19: 399 | X19: 136 | Y19: 263
C20: 10 | D20: Persons ministering to Amusement | E20: 155 | F20: 120 | G20: 35 | H20: 0 | I20: 0 | J20: 0 | K20: 1 | L20: 1 | M20: 0 | N20: 0 | O20: 0 | P20: 0 | Q20: 6 | R20: 6 | S20: 0 | T20: 13 | U20: 10 | V20: 3 | W20: 175 | X20: 137 | Y20: 38
A22: II. | B22: III. | D22: Wives, Widows, Daughters, and other Relatives engaged in Domestic Duties | E22: 69730 | F22: 13 | G22: 48717 | H22: 2312 | I22: 0 | J22: 2312 | K22: 5721 | L22: 1 | M22: 5720 | N22: 2679 | O22: 3 | P22: 2676 | Q22: 14828 | R22: 6 | S22: 14822 | T22: 33675 | U22: 12 | V22: 33663 | W22: 128945 | X22: 35 | Y22: 128910
B24: IV. | C24: 1 | D24: Engaged in Board and Lodging | E24: 1492 | F24: 708 | G24: 604 | H24: 5 | I24: 1 | J24: 4 | K24: 1 | L24: 0 | M24: 1 | N24: 13 | O24: 7 | P24: 6 | Q24: 47 | R24: 27 | S24: 20 | T24: 51 | U24: 21 | V24: 30 | W24: 1609 | X24: 854 | Y24: 755
C25: 2 | D25: Engaged in Attendance | E25: 5896 | F25: 1437 | G25: 4459 | H25: 2364 | I25: 359 | J25: 2005 | K25: 7884 | L25: 1477 | M25: 6407 | N25: 3154 | O25: 674 | P25: 2480 | Q25: 18304 | R25: 5126 | S25: 13178 | T25: 34982 | U25: 5980 | V25: 29002 | W25: 72584 | X25: 15053 | Y25: 57531
A27: III. | B27: V. | C27: 1 | D27: Engaged in Merchantile Pursuits | E27: 10788 | F27: 9490 | G27: 1298 | H27: 92 | I27: 74 | J27: 18 | K27: 13 | L27: 12 | M27: 1 | N27: 41 | O27: 40 | P27: 1 | Q27: 144 | R27: 123 | S27: 21 | T27: 1007 | U27: 897 | V27: 110 | W27: 12085 | X27: 10636 | Y27: 1449
B29: VI. | C29: 1 | D29: Carriers on Railways | E29: 1733 | F29: 1720 | G29: 13 | H29: 7 | I29: 7 | J29: 0 | K29: 10 | L29: 9 | M29: 1 | N29: 49 | O29: 49 | P29: 0 | Q29: 107 | R29: 107 | S29: 0 | T29: 286 | U29: 278 | V29: 8 | W29: 2192 | X29: 2170 | Y29: 22
C30: 2 | D30: Carriers on Roads | E30: 2122 | F30: 2074 | G30: 48 | H30: 369 | I30: 367 | J30: 2 | K30: 329 | L30: 328 | M30: 1 | N30: 356 | O30: 354 | P30: 2 | Q30: 1249 | R30: 1247 | S30: 2 | T30: 1952 | U30: 1940 | V30: 12 | W30: 6377 | X30: 6310 | Y30: 67
C31: 3 | D31: Carriers on Seas and Rivers | E31: 1822 | F31: 1817 | G31: 5 | H31: 31 | I31: 31 | J31: 0 | K31: 15 | L31: 15 | M31: 0 | N31: 12 | O31: 12 | P31: 0 | Q31: 43 | R31: 43 | S31: 0 | T31: 217 | U31: 217 | V31: 0 | W31: 2140 | X31: 2135 | Y31: 5
C32: 4 | D32: Engaged in Storage | E32: 245 | F32: 245 | G32: 0 | H32: 35 | I32: 35 | J32: 0 | K32: 30 | L32: 30 | M32: 0 | N32: 142 | O32: 142 | P32: 0 | Q32: 673 | R32: 669 | S32: 4 | T32: 389 | U32: 389 | V32: 0 | W32: 1514 | X32: 1510 | Y32: 4
C33: 5 | D33: Postal and Electronic Telegraph Services | E33: 1040 | F33: 1003 | G33: 37 | H33: 4 | I33: 4 | J33: 0 | K33: 10 | L33: 10 | M33: 0 | N33: 27 | O33: 27 | P33: 0 | Q33: 55 | R33: 54 | S33: 1 | T33: 149 | U33: 148 | V33: 1 | W33: 1285 | X33: 1246 | Y33: 39
C34: 6 | D34: Messengers and Porter | E34: 172 | F34: 170 | G34: 2 | H34: 29 | I34: 19 | J34: 1 | K34: 18 | L34: 15 | M34: 3 | N34: 11 | O34: 11 | P34: 0 | Q34: 86 | R34: 82 | S34: 4 | T34: 216 | U34: 208 | V34: 8 | W34: 523 | X34: 505 | Y34: 18
A36: IV. | B36: VII. | C36: 1 | D36: Engaged in Agriculture Pursuits and Pastoral Pursuits | E36: 72645 | F36: 58064 | G36: 14581 | H36: 188 | I36: 171 | J36: 14 | K36: 16506 | L36: 13250 | M36: 3256 | N36: 142388 | O36: 66913 | P36: 75475 | Q36: 382397 | R36: 195171 | S36: 187226 | T36: 52100 | U36: 43868 | V36: 8232 | W36: 666224 | X36: 377440 | Y36: 288784
C37: 2 | D37: Engaged in Woods and Forests | E37: 971 | F37: 966 | G37: 5 | H37: 76 | I37: 76 | J37: 0 | K37: 175 | L37: 175 | M37: 0 | N37: 65 | O37: 62 | P37: 3 | Q37: 335 | R37: 305 | S37: 30 | T37: 612 | U37: 601 | V37: 11 | W37: 2234 | X37: 2185 | Y37: 49
C38: 3 | D38: Engaged on Land (not cultivating or grazing) | E38: 21 | F38: 21 | G38: 0 | H38: 0 | I38: 0 | J38: 0 | K38: 6 | L38: 6 | M38: 0 | N38: 6 | O38: 6 | P38: 0 | Q38: 29 | R38: 29 | S38: 0 | T38: 6 | U38: 6 | V38: 0 | W38: 68 | X38: 68 | Y38: 0
C39: 4 | D39: Engaged about Animals | E39: 458 | F39: 458 | G39: 0 | H39: 252 | I39: 252 | J39: 0 | K39: 173 | L39: 171 | M39: 2 | N39: 484 | O39: 484 | P39: 0 | Q39: 1199 | R39: 1195 | S39: 4 | T39: 1366 | U39: 1359 | V39: 7 | W39: 3932 | X39: 3919 | Y39: 13
A41: V. | B41: VIII. | C41: 1 | D41: Engaged in Books | E41: 946 | F41: 887 | G41: 59 | H41: 8 | I41: 8 | J41: 0 | K41: 1 | L41: 1 | M41: 0 | N41: 15 | O41: 15 | P41: 0 | Q41: 34 | R41: 34 | S41: 0 | T41: 157 | U41: 141 | V41: 16 | W41: 1161 | X41: 1086 | Y41: 75
C42: 2 | D42: Engaged in Musical Instrumemts | E42: 48 | F42: 48 | G42: 0 | H42: 0 | I42: 0 | J42: 0 | K42: 0 | L42: 0 | M42: 0 | N42: 0 | O42: 0 | P42: 0 | Q42: 0 | R42: 0 | S42: 0 | T42: 1 | U42: 1 | W42: 49 | X42: 49 | Y42: 0
C43: 3 | D43: Engaged in Prints and Pictures | E43: 21 | F43: 21 | G43: 0 | H43: 0 | I43: 0 | J43: 0 | K43: 0 | L43: 0 | M43: 0 | N43: 0 | O43: 0 | P43: 0 | Q43: 0 | R43: 0 | S43: 0 | T43: 4 | U43: 1 | V43: 3 | W43: 25 | X43: 22 | Y43: 3
C44: 4 | D44: Engaged in Carving and Figures | E44: 4 | F44: 4 | G44: 0 | H44: 0 | I44: 0 | J44: 0 | K44: 0 | L44: 0 | M44: 0 | N44: 0 | O44: 0 | P44: 0 | Q44: 0 | R44: 0 | S44: 0 | T44: 0 | U44: 0 | V44: 0 | W44: 4 | X44: 4 | Y44: 0
C45: 5 | D45: Engaged in Designs | E45: 15 | F45: 15 | G45: 0 | H45: 0 | I45: 0 | J45: 0 | K45: 0 | L45: 0 | M45: 0 | N45: 0 | O45: 0 | P45: 0 | Q45: 0 | R45: 0 | S45: 0 | T45: 0 | U45: 0 | V45: 0 | W45: 15 | X45: 15 | Y45: 0
C46: 6 | D46: Engaged in Watches | E46: 205 | F46: 205 | G46: 0 | H46: 3 | I46: 3 | J46: 0 | K46: 0 | L46: 0 | M46: 0 | N46: 0 | O46: 0 | P46: 0 | Q46: 0 | R46: 0 | S46: 0 | T46: 7 | U46: 7 | W46: 215 | X46: 215 | Y46: 0
C47: 7 | D47: Engaged in Surgical Instruments | E47: 6 | F47: 6 | G47: 0 | H47: 0 | I47: 0 | J47: 0 | K47: 0 | L47: 0 | M47: 0 | N47: 0 | O47: 0 | P47: 0 | Q47: 0 | R47: 0 | S47: 0 | T47: 0 | U47: 0 | V47: 0 | W47: 6 | X47: 6 | Y47: 0
...

Sheet 1904
A1: TABLE VII.. - OCCUPATIONS. - Shewing the Occupations of the Population of the Colony, according to the Censuses of 1904
A2: CLASS. | B2: ORDER. | C2: SUB-ORDER. | D2: OCCUPATIONS | E2: TOTAL. | H2: EUROPEAN OR WHITE. | K2: Malay | N2: Hottentot. | Q2: Fingo. | T2: Kafir and Bechuana | W2: Mixed and Other.
E3: Persons. | F3: Males. | G3: Females | H3: Persons. | I3: Males. | J3: Females | K3: Persons. | L3: Males. | M3: Females | N3: Persons. | O3: Males. | P3: Females | Q3: Persons. | R3: Males. | S3: Females | T3: Persons. | U3: Males. | V3: Females | W3: Persons. | X3: Males. | Y3: Females
D5: Total Population | E5: 2409805 | F5: 2118940 | G5: 1190864 | H5: 579741 | I5: 318544 | J5: 261197 | K5: 15682 | L5: 7882 | M5: 7800 | N5: 91260 | O5: 47027 | P5: 44233 | Q5: 310720 | R5: 147286 | S5: 163434 | T5: 1115067 | U5: 545442 | V5: 568625 | W5: 298334 | X5: 152759 | Y5: 145575 | AA5: European/White working age male population
AB6: 1904 | AC6: 19.04
A7: I. | B7: I. | C7: 1 | D7: Officers of General Government | E7: 7916 | F7: 7774 | G7: 142 | H7: 5906 | I7: 5776 | J7: 130 | K7: 2 | L7: 2 | M7: 0 | N7: 23 | O7: 22 | P7: 2 | Q7: 523 | R7: 521 | S7: 2 | T7: 1287 | U7: 1285 | V7: 2 | W7: 175 | X7: 168 | Y7: 7 | AA7: White collar | AB7: =I7+I8+I9+I11+I12+I13+I14+I15+I16+I17+I18+I19+I20+I24+I27+I29+I31+I30+I33+I32+I41+I42+I43+I44+I45+I46+I47+I48+I49+I50+I51+I52+I53 -> 76068 | AC7: =AB7/$AB$11*100 -> 36.969824
C8: 2 | D8: Officers of Local Government | E8: 540 | F8: 533 | G8: 7 | H8: 518 | I8: 512 | J8: 6 | K8: 1 | L8: 1 | M8: 0 | N8: 2 | O8: 2 | P8: 0 | Q8: 1 | R8: 1 | S8: 0 | T8: 4 | U8: 4 | V8: 0 | W8: 14 | X8: 13 | Y8: 1 | AA8: Farmer | AB8: =I36+I37+I38+I39 -> 72802 | AC8: =AB8/$AB$11*100 -> 35.382514
C9: 3 | D9: Engaged in Defence | E9: 9994 | F9: 9994 | G9: 0 | H9: 9713 | I9: 9713 | J9: 0 | K9: 2 | L9: 2 | M9: 0 | N9: 8 | O9: 8 | P9: 0 | Q9: 12 | R9: 12 | S9: 0 | T9: 53 | U9: 53 | V9: 0 | W9: 206 | X9: 206 | Y9: 0 | AA9: Skilled/semi-skilled | AB9: =I55+I56+I57+I58+I60+I61+I62+I64+I65+I66+I68+I69+I71++I72+I73+I74+I75+I76+I77 -> 45651 | AC9: =AB9/$AB$11*100 -> 22.186851
AA10: Unskilled | AB10: =I79+I25+I34 -> 11236 | AC10: =AB10/$AB$11*100 -> 5.4608106
B11: II. | C11: 1 | D11: Clergymen, Ministers, and Church Officers | E11: 2122 | F11: 1782 | G11: 340 | H11: 1480 | I11: 1151 | J11: 329 | K11: 37 | L11: 37 | M11: 0 | N11: 10 | O11: 9 | P11: 1 | Q11: 232 | R11: 228 | S11: 4 | T11: 299 | U11: 297 | V11: 2 | W11: 64 | X11: 60 | Y11: 4 | AA11: Total working age | AB11: =SUM(AB7:AB10) -> 205757 | AC11: =AB11/$AB$11*100 -> 100
C12: 2 | D12: Law Court Officers, Barristers, Attorneys and Law Agents and Immediate Subordinates | E12: 1647 | F12: 1635 | G12: 12 | H12: 1511 | I12: 1500 | J12: 11 | K12: 0 | L12: 0 | M12: 0 | N12: 1 | O12: 1 | P12: 0 | Q12: 51 | R12: 50 | S12: 1 | T12: 71 | U12: 71 | V12: 0 | W12: 13 | X12: 13 | Y12: 0
C13: 3 | D13: Physicians, Surgeons, Chemists, &c. | E13: 3161 | F13: 1822 | G13: 1339 | H13: 2546 | I13: 1597 | J13: 949 | K13: 14 | L13: 1 | M13: 13 | N13: 40 | O13: 4 | P13: 36 | Q13: 63 | R13: 51 | S13: 12 | T13: 195 | U13: 136 | V13: 59 | W13: 303 | X13: 33 | Y13: 270
C14: 4 | D14: Literary Persons | E14: 925 | F14: 307 | G14: 618 | H14: 896 | I14: 279 | J14: 617 | K14: 0 | L14: 0 | M14: 0 | N14: 0 | O14: 0 | P14: 0 | Q14: 3 | R14: 3 | T14: 8 | U14: 8 | V14: 0 | W14: 18 | X14: 17 | Y14: 1
C15: 5 | D15: Scientific Persons | E15: 48 | F15: 48 | G15: 0 | H15: 48 | I15: 48 | J15: 0 | K15: 0 | L15: 0 | M15: 0 | N15: 0 | O15: 0 | P15: 0 | Q15: 0 | R15: 0 | S15: 0 | T15: 0 | U15: 0 | V15: 0 | W15: 0 | X15: 0 | Y15: 0
C16: 6 | D16: Engineering, Surveying and Architechture | E16: 1598 | F16: 1595 | G16: 3 | H16: 1583 | I16: 1580 | J16: 3 | K16: 0 | L16: 0 | M16: 0 | N16: 0 | O16: 0 | P16: 0 | Q16: 0 | R16: 0 | S16: 0 | T16: 0 | U16: 0 | V16: 0 | W16: 15 | X16: 15 | Y16: 0
C17: 7 | D17: Teachers, &c. | E17: 8548 | F17: 2492 | G17: 6056 | H17: 6257 | I17: 1393 | J17: 4864 | K17: 10 | L17: 8 | M17: 2 | N17: 24 | O17: 8 | P17: 16 | Q17: 1053 | R17: 486 | S17: 567 | T17: 806 | U17: 460 | V17: 346 | W17: 389 | X17: 137 | Y17: 261
C18: 8 | D18: Artists | E18: 591 | F18: 495 | G18: 96 | H18: 579 | I18: 485 | J18: 94 | K18: 0 | L18: 0 | M18: 0 | N18: 0 | O18: 0 | P18: 0 | Q18: 0 | R18: 0 | S18: 0 | T18: 0 | U18: 0 | V18: 0 | W18: 12 | X18: 10 | Y18: 2
C19: 9 | D19: Musicians, Music Teachers | E19: 750 | F19: 248 | G19: 502 | H19: 737 | I19: 243 | J19: 494 | K19: 0 | L19: 0 | M19: 0 | N19: 0 | O19: 0 | P19: 0 | Q19: 0 | R19: 0 | S19: 0 | T19: 1 | U19: 1 | V19: 0 | W19: 12 | X19: 4 | Y19: 8
C20: 10 | D20: Persons ministering to Amusement | E20: 471 | F20: 375 | G20: 96 | H20: 428 | I20: 334 | J20: 94 | K20: 0 | L20: 0 | M20: 0 | N20: 0 | O20: 0 | P20: 0 | Q20: 0 | R20: 0 | S20: 0 | T20: 3 | U20: 3 | V20: 0 | W20: 39 | X20: 37 | Y20: 2
A22: II. | B22: III. | D22: Wives, Widows, Daughters, and other Relatives engaged in Domestic Duties | E22: 176874 | F22: 299 | G22: 176575 | H22: 85468 | I22: 86 | J22: 85382 | K22: 2784 | L22: 7 | M22: 2777 | N22: 11254 | O22: 31 | P22: 11223 | Q22: 4505 | R22: 15 | S22: 4490 | T22: 28100 | U22: 72 | V22: 28028 | W22: 44763 | X22: 88 | Y22: 44675
B24: IV. | C24: 1 | D24: Engaged in Board and Lodging | E24: 3298 | F24: 1695 | G24: 1603 | H24: 3047 | I24: 1571 | J24: 1476 | K24: 1 | L24: 1 | M24: 0 | N24: 1 | O24: 1 | P24: 0 | Q24: 63 | R24: 23 | S24: 40 | T24: 98 | U24: 53 | V24: 45 | W24: 88 | X24: 46 | Y24: 42
C25: 2 | D25: Engaged in Attendance | E25: 98598 | F25: 15201 | G25: 83397 | H25: 10804 | I25: 2976 | J25: 7828 | K25: 1998 | L25: 174 | M25: 1824 | N25: 13468 | O25: 1574 | P25: 11912 | Q25: 4623 | R25: 629 | S25: 3994 | T25: 29408 | U25: 4437 | V25: 24971 | W25: 38279 | X25: 5411 | Y25: 32868
A27: III. | B27: V. | C27: 1 | D27: Engaged in Merchantile Pursuits | E27: 33008 | F27: 29811 | G27: 3197 | H27: 28095 | I27: 25214 | J27: 2881 | K27: 319 | L27: 304 | M27: 15 | N27: 48 | O27: 47 | P27: 1 | Q27: 131 | R27: 112 | S27: 19 | T27: 380 | U27: 356 | V27: 24 | W27: 4035 | X27: 3778 | Y27: 257
B29: VI. | C29: 1 | D29: Carriers on Railways | E29: 8013 | F29: 7968 | G29: 45 | H29: 6771 | I29: 6738 | J29: 33 | K29: 11 | L29: 11 | M29: 0 | N29: 78 | O29: 77 | P29: 1 | Q29: 91 | R29: 90 | S29: 1 | T29: 412 | U29: 411 | V29: 1 | W29: 650 | X29: 641 | Y29: 9
C30: 2 | D30: Carriers on Roads | E30: 12987 | F30: 12951 | G30: 36 | H30: 3998 | I30: 3976 | J30: 22 | K30: 566 | L30: 564 | M30: 2 | N30: 615 | O30: 615 | P30: 0 | Q30: 922 | R30: 922 | S30: 0 | T30: 2505 | U30: 2504 | V30: 1 | W30: 4381 | X30: 4370 | Y30: 11
C31: 3 | D31: Carriers on Seas and Rivers | E31: 4807 | F31: 4790 | G31: 17 | H31: 4033 | I31: 4016 | J31: 17 | K31: 12 | L31: 12 | M31: 0 | N31: 20 | O31: 20 | P31: 0 | Q31: 6 | R31: 6 | S31: 0 | T31: 72 | U31: 72 | V31: 0 | W31: 664 | X31: 664 | Y31: 0
C32: 4 | D32: Engaged in Storage | E32: 5331 | F32: 5326 | G32: 5 | H32: 245 | I32: 245 | K32: 38 | L32: 38 | M32: 0 | N32: 227 | O32: 227 | P32: 0 | Q32: 793 | R32: 791 | S32: 2 | T32: 2647 | U32: 2647 | V32: 0 | W32: 1381 | X32: 1378 | Y32: 3
C33: 5 | D33: Postal and Electronic Telegraph Services | E33: 3406 | F33: 3261 | G33: 145 | H33: 2859 | I33: 2721 | J33: 138 | K33: 16 | L33: 16 | M33: 0 | N33: 32 | O33: 31 | P33: 1 | Q33: 47 | R33: 47 | S33: 0 | T33: 141 | U33: 136 | V33: 5 | W33: 311 | X33: 310 | Y33: 1
C34: 6 | D34: Messengers and Porter | E34: 1723 | F34: 1705 | G34: 18 | H34: 749 | I34: 740 | J34: 9 | K34: 39 | L34: 38 | M34: 1 | N34: 46 | O34: 46 | P34: 0 | Q34: 65 | R34: 65 | S34: 0 | T34: 239 | U34: 234 | V34: 5 | W34: 585 | X34: 582 | Y34: 3
A36: IV. | B36: VII. | C36: 1 | D36: Engaged in Agriculture Pursuits and Pastoral Pursuits | E36: 1002264 | F36: 517053 | G36: 485211 | H36: 108638 | I36: 70278 | J36: 38360 | K36: 204 | L36: 186 | M36: 18 | N36: 25025 | O36: 20347 | P36: 4678 | Q36: 172286 | R36: 77814 | S36: 94472 | T36: 650622 | U36: 310366 | V36: 340256 | W36: 45489 | X36: 38062 | Y36: 7427
C37: 2 | D37: Engaged in Woods and Forests | E37: 2361 | F37: 2344 | G37: 17 | H37: 906 | I37: 905 | J37: 1 | K37: 45 | L37: 45 | M37: 0 | N37: 147 | O37: 146 | P37: 1 | Q37: 84 | R37: 84 | S37: 0 | T37: 531 | U37: 518 | V37: 13 | W37: 648 | X37: 646 | Y37: 2
C38: 3 | D38: Engaged on Land (not cultivating or grazing) | E38: 124 | F38: 123 | G38: 1 | H38: 16 | I38: 15 | J38: 1 | K38: 0 | L38: 0 | M38: 0 | N38: 16 | O38: 16 | P38: 0 | Q38: 3 | R38: 3 | S38: 0 | T38: 78 | U38: 78 | V38: 0 | W38: 11 | X38: 11 | Y38: 0
C39: 4 | D39: Engaged about Animals | E39: 4725 | F39: 4708 | G39: 17 | H39: 1615 | I39: 1604 | J39: 11 | K39: 287 | L39: 286 | M39: 1 | N39: 196 | O39: 195 | P39: 1 | Q39: 166 | R39: 166 | S39: 0 | T39: 568 | U39: 568 | V39: 0 | W39: 1893 | X39: 1889 | Y39: 4
A41: V. | B41: VIII. | C41: 1 | D41: Engaged in Books | E41: 2105 | F41: 1886 | G41: 219 | H41: 1728 | I41: 1560 | J41: 168 | K41: 15 | L41: 13 | M41: 2 | N41: 1 | O41: 1 | P41: 0 | Q41: 34 | R41: 34 | S41: 0 | T41: 36 | U41: 36 | V41: 0 | W41: 291 | X41: 212 | Y41: 49
C42: 2 | D42: Engaged in Musical Instrumemts | E42: 121 | F42: 113 | G42: 8 | H42: 121 | I42: 113 | J42: 8 | K42: 0 | L42: 0 | M42: 0 | N42: 0 | O42: 0 | P42: 0 | Q42: 0 | R42: 0 | S42: 0 | T42: 0 | U42: 0 | V42: 0 | W42: 0 | X42: 0 | Y42: 0
C43: 3 | D43: Engaged in Prints and Pictures | E43: 36 | F43: 33 | G43: 3 | H43: 34 | I43: 31 | J43: 3 | K43: 0 | L43: 0 | M43: 0 | N43: 0 | O43: 0 | P43: 0 | Q43: 0 | R43: 0 | S43: 0 | T43: 0 | U43: 0 | V43: 0 | W43: 0 | X43: 0 | Y43: 0
C44: 4 | D44: Engaged in Carving and Figures | E44: 80 | F44: 77 | G44: 3 | H44: 56 | I44: 54 | J44: 2 | K44: 0 | L44: 0 | M44: 0 | N44: 0 | O44: 0 | P44: 0 | Q44: 2 | R44: 2 | S44: 0 | T44: 3 | U44: 3 | V44: 0 | W44: 19 | X44: 18 | Y44: 1
C45: 5 | D45: Engaged in Designs | E45: 91 | F45: 90 | G45: 1 | H45: 87 | I45: 84 | J45: 3 | K45: 0 | L45: 0 | M45: 0 | N45: 0 | O45: 0 | P45: 0 | Q45: 0 | R45: 0 | S45: 0 | T45: 0 | U45: 0 | V45: 0 | W45: 0 | X45: 0 | Y45: 0
C46: 6 | D46: Engaged in Watches | E46: 123 | F46: 121 | G46: 2 | H46: 104 | I46: 102 | J46: 2 | K46: 0 | L46: 0 | M46: 0 | N46: 0 | O46: 0 | P46: 0 | Q46: 2 | R46: 2 | S46: 0 | T46: 0 | U46: 0 | V46: 0 | W46: 16 | X46: 16 | Y46: 0
C47: 7 | D47: Engaged in Surgical Instruments | E47: 12 | F47: 12 | G47: 0 | H47: 12 | I47: 12 | J47: 0 | K47: 0 | L47: 0 | M47: 0 | N47: 0 | O47: 0 | P47: 0 | Q47: 0 | R47: 0 | S47: 0 | T47: 0 | U47: 0 | V47: 0 | W47: 0 | X47: 0 | Y47: 0
...

Sheet 1911
A1: The Union Of South Africa | C1: Page | D1: Total | E1: Urban | I1: Total | J1: Rural
E2: European or White | G2: Other than European or White | J2: European or White | L2: Other than European or White
E3: Male | F3: Female | G3: Male | H3: Female | J3: Male | K3: Female | L3: Male | M3: Female
A5: Occupations
A6: I Proffesional | C6: 674- 675 | P6: White collar
A7: A) General or Local Government | P7: Farmer
A8: 1 | B8: Union and Provincial Government | D8: =SUM(E8:H8) -> 11769 | E8: 8291 | F8: 258 | G8: 3211 | H8: 9 | I8: =SUM(J8:M8) -> 5055 | J8: 2176 | K8: 20 | L8: 2855 | M8: 4 | P8: Skilled/semi-skilled
A9: 2 | B9: Local Government | D9: =SUM(E9:H9) -> 1778 | E9: 1685 | F9: 13 | G9: 80 | I9: =SUM(J9:M9) -> 65 | J9: 56 | L9: 9 | P9: Unskilled
A10: 3 | B10: Defence of the Country | D10: =SUM(E10:H10) -> 13112 | E10: 12924 | G10: 188 | I10: =SUM(J10:M10) -> 560 | J10: 519 | L10: 41
A11: 4 | B11: Officers of Foreign Government | D11: =SUM(E11:H11) -> 247 | E11: 233 | F11: 1 | G11: 13 | I11: =SUM(J11:M11) -> 1 | J11: 1
A12: B) Religion, Charity, Law, Health, Educ etc.
A13: 1 | B13: Religion and Charity | D13: =SUM(E13:H13) -> 3251 | E13: 1810 | F13: 757 | G13: 671 | H13: 13 | I13: =SUM(J13:M13) -> 2235 | J13: 745 | K13: 508 | L13: 961 | M13: 21
A14: 2 | B14: Law | D14: =SUM(E14:H14) -> 3621 | E14: 3382 | F14: 55 | G14: 184 | I14: =SUM(J14:M14) -> 438 | J14: 364 | K14: 2 | L14: 71 | M14: 1
A15: 3 | B15: Public Healt | D15: =SUM(E15:H15) -> 6293 | E15: 2892 | F15: 2484 | G15: 602 | H15: 315 | I15: =SUM(J15:M15) -> 945 | J15: 267 | K15: 314 | L15: 257 | M15: 107
A16: 4 | B16: Literature | D16: =SUM(E16:H16) -> 636 | E16: 459 | F16: 172 | G16: 5 | I16: =SUM(J16:M16) -> 22 | J16: 12 | K16: 8 | L16: 2
A17: 5 | B17: Science | D17: =SUM(E17:H17) -> 289 | E17: 265 | F17: 20 | G17: 4 | I17: =SUM(J17:M17) -> 41 | J17: 40 | K17: 1
A18: 6 | B18: Engineering, Surveying, Architecture | D18: =SUM(E18:H18) -> 1247 | E18: 1238 | F18: 2 | G18: 7 | I18: =SUM(J18:M18) -> 199 | J18: 189 | K18: 1 | L18: 9
A19: 7 | B19: Education | D19: =SUM(E19:H19) -> 8559 | E19: 2148 | F19: 5395 | G19: 575 | H19: 441 | I19: =SUM(J19:M19) -> 9341 | J19: 2048 | K19: 4162 | L19: 1964 | M19: 1167
A20: 8 | B20: Fine Arts | D20: =SUM(E20:H20) -> 947 | E20: 682 | F20: 199 | G20: 60 | H20: 6 | I20: =SUM(J20:M20) -> 91 | J20: 77 | K20: 11 | L20: 3
A21: 9 | B21: Music | D21: =SUM(E21:H21) -> 1546 | E21: 443 | F21: 1067 | G21: 29 | H21: 7 | I21: =SUM(J21:M21) -> 85 | J21: 12 | K21: 72 | L21: 1
A22: 10 | B22: Amusement | D22: =SUM(E22:H22) -> 1119 | E22: 798 | F22: 193 | G22: 123 | H22: 5 | I22: =SUM(J22:M22) -> 40 | J22: 22 | K22: 3 | L22: 14 | M22: 1
A23: II Domestic
A24: C) Domestic Offices or Household Duties
A25: 1 | B25: Wives, Widows, Daughters, other Relatives | D25: =SUM(E25:H25) -> 210129 | E25: 12 | F25: 142042 | G25: 12 | H25: 68063 | I25: =SUM(J25:M25) -> 241297 | J25: 32 | K25: 124225 | L25: 28 | M25: 117012
A26: D) Supply of Board and Lodging, Attendance
A27: 1 | B27: Supply of Board and Lodging | D27: =SUM(E27:H27) -> 4367 | E27: 2420 | F27: 1659 | G27: 214 | H27: 74 | I27: =SUM(J27:M27) -> 610 | J27: 392 | K27: 174 | L27: 31 | M27: 13
A28: 2 | B28: Engaged in Attendance | D28: =SUM(E28:H28) -> 144247 | E28: 4911 | F28: 9913 | G28: 66204 | H28: 63219 | I28: =SUM(J28:M28) -> 135579 | J28: 1205 | K28: 3172 | L28: 50459 | M28: 80743
A29: III Commercial
A30: E) Buying, Selling, Exchanging, Insuring etc.
A31: 1 | B31: Mercantile Persons | D31: =SUM(E31:H31) -> 56505 | E31: 35408 | F31: 5531 | G31: 15232 | H31: 334 | I31: =SUM(J31:M31) -> 12096 | J31: 7623 | K31: 392 | L31: 4021 | M31: 60
A32: F) Conveyance of Men, Animals, Goods etc.
A33: 1 | B33: Rail | D33: =SUM(E33:H33) -> 12747 | E33: 11280 | F33: 72 | G33: 1390 | H33: 5 | I33: =SUM(J33:M33) -> 2903 | J33: 2305 | K33: 12 | L33: 578 | M33: 8
A34: 2 | B34: Tramways and Roads | D34: =SUM(E34:H34) -> 16391 | E34: 5577 | F34: 23 | G34: 10785 | H34: 6 | I34: =SUM(J34:M34) -> 5929 | J34: 1486 | K34: 6 | L34: 4424 | M34: 13
A35: 3 | B35: Sea and River | D35: =SUM(E35:H35) -> 4984 | E35: 3963 | F35: 29 | G35: 992 | I35: =SUM(J35:M35) -> 262 | J35: 188 | L35: 74
A36: 4 | B36: Storage | D36: =SUM(E36:H36) -> 1783 | E36: 430 | F36: 6 | G36: 1344 | H36: 3 | I36: =SUM(J36:M36) -> 2 | J36: 2
A37: 5 | B37: Post and Telegraph Service | D37: =SUM(E37:H37) -> 5364 | E37: 4243 | F37: 372 | G37: 746 | H37: 3 | I37: =SUM(J37:M37) -> 771 | J37: 385 | K37: 71 | L37: 308 | M37: 7
A38: 6 | B38: Others engaged in Conveyance | D38: =SUM(E38:H38) -> 2832 | E38: 1057 | F38: 6 | G38: 1765 | H38: 4 | I38: =SUM(J38:M38) -> 238 | J38: 35 | L38: 202 | M38: 1
A39: IV Agricultural | C39: 676- 677
A40: G) Working, Cultivating Land and Animals
A41: 1 | B41: Agricultural or Pastoral Pursuits | D41: =SUM(E41:H41) -> 79630 | E41: 14113 | F41: 1136 | G41: 39610 | H41: 24771 | I41: =SUM(J41:M41) -> 2096676 | J41: 150519 | K41: 23015 | L41: 866576 | M41: 1056566
...

Sheet Summaries
A1: European/White working age male population from available censuses (frequencies)
B2: 1865 | C2: 1875 | D2: 1891 | E2: 1911
A3: White collar | B3: ='1865 v. 1875'!K8+'1865 v. 1875'!K9+'1865 v. 1875'!K10+'1865 v. 1875'!K12+'1865 v. 1875'!K13+'1865 v. 1875'!K14+'1865 v. 1875'!K15+'1865 v. 1875'!K16+'1865 v. 1875'!K17+'1865 v. 1875'!K18+'1865 v. 1875'!K24+'1865 v. 1875'!K27+'1865 v. 1875'!K30+'1865 v. 1875'!K32+'1865 v. 1875'!K34+'1865 v. 1875'!K41+'1865 v. 1875'!K46+'1865 v. 1875'!K47+'1865 v. 1875'!K49+'1865 v. 1875'!K50+'1865 v. 1875'!K51+'1865 v. 1875'!K53 -> 14423 | C3: ='1865 v. 1875'!M8+'1865 v. 1875'!M9+'1865 v. 1875'!M10+'1865 v. 1875'!M12+'1865 v. 1875'!M13+'1865 v. 1875'!M14+'1865 v. 1875'!M15+'1865 v. 1875'!M16+'1865 v. 1875'!M17+'1865 v. 1875'!M18+'1865 v. 1875'!M19+'1865 v. 1875'!M20+'1865 v. 1875'!M24+'1865 v. 1875'!M27+'1865 v. 1875'!M28+'1865 v. 1875'!M30+'1865 v. 1875'!M31+'1865 v. 1875'!M32+'1865 v. 1875'!M33+'1865 v. 1875'!M34+'1865 v. 1875'!M41+'1865 v. 1875'!M42+'1865 v. 1875'!M43+'1865 v. 1875'!M44+'1865 v. 1875'!M45+'1865 v. 1875'!M46+'1865 v. 1875'!M47+'1865 v. 1875'!M48+'1865 v. 1875'!M49+'1865 v. 1875'!M50+'1865 v. 1875'!M51+'1865 v. 1875'!M52+'1865 v. 1875'!M53 -> 21886 | D3: 31715 | E3: 144648
A4: Farmer | B4: ='1865 v. 1875'!K36+'1865 v. 1875'!K37+'1865 v. 1875'!K39 -> 26829 | C4: ='1865 v. 1875'!M36+'1865 v. 1875'!M37+'1865 v. 1875'!M38+'1865 v. 1875'!M39 -> 34069 | D4: 59509 | E4: 236057
A5: Skilled/semi-skilled | B5: ='1865 v. 1875'!K55+'1865 v. 1875'!K56+'1865 v. 1875'!K59+'1865 v. 1875'!K60+'1865 v. 1875'!K61+'1865 v. 1875'!K63+'1865 v. 1875'!K64+'1865 v. 1875'!K66+'1865 v. 1875'!K67+'1865 v. 1875'!K68+'1865 v. 1875'!K72 -> 3620 | C5: ='1865 v. 1875'!M55+'1865 v. 1875'!M56+'1865 v. 1875'!M57+'1865 v. 1875'!M59+'1865 v. 1875'!M60+'1865 v. 1875'!M61+'1865 v. 1875'!M63+'1865 v. 1875'!M64+'1865 v. 1875'!M66+'1865 v. 1875'!M67+'1865 v. 1875'!M68+'1865 v. 1875'!M70+'1865 v. 1875'!M72 -> 5700 | D5: 20075 | E5: 93945
A6: Unskilled | B6: ='1865 v. 1875'!K25+'1865 v. 1875'!K74+'1865 v. 1875'!K75 -> 3613 | C6: ='1865 v. 1875'!M25+'1865 v. 1875'!M74+'1865 v. 1875'!M75 -> 3069 | D6: 2269 | E6: 18912
A7: Total working age pop | B7: =SUM(B3:B6) -> 48485 | C7: =SUM(C3:C6) -> 64724 | D7: 113568 | E7: 493562
B10: SAF Slavery | C10: SAF Stagnation | D10: Census 1865 | E10: SAF Diamonds | F10: Census 1875 | G10: Census 1891 | H10: SAF Gold | I10: Census 1911
A11: White collar | B11: 17.22 | C11: 20.59 | D11: =B3/$B$7*100 -> 29.747345 | E11: 26.6 | F11: =C3/$C$7*100 -> 33.81435 | G11: 27.926 | H11: 34.79 | I11: 29.306956
A12: Farmer | B12: 64.62 | C12: 61.74 | D12: =B4/$B$7*100 -> 55.33464 | E12: 60.18 | F12: =C4/$C$7*100 -> 52.637352 | G12: 52.399444 | H12: 49.73 | I12: 47.827223
A13: Skilled/semi-skilled | B13: 9.85 | C13: 8.11 | D13: =B5/$B$7*100 -> 7.4662267 | E13: 9.03 | F13: =C5/$C$7*100 -> 8.8066251 | G13: 17.676634 | H13: 12.45 | I13: 19.034083
A14: Unskilled | B14: 8.3 | C14: 9.56 | D14: =B6/$B$7*100 -> 7.4517892 | E14: 4.19 | F14: =C6/$C$7*100 -> 4.7416723 | G14: 1.9979219 | H14: 3.04 | I14: 3.8317375
A15: Total working age pop | B15: =SUM(B11:B14) -> 99.99 | C15: =SUM(C11:C14) -> 100 | D15: =SUM(D11:D14) -> 100 | E15: =SUM(E11:E14) -> 100 | F15: =SUM(F11:F14) -> 100 | G15: =SUM(G11:G14) -> 100 | H15: =SUM(H11:H14) -> 100.01 | I15: =SUM(I11:I14) -> 100
A22: European/White working age male population from available censuses (proportions) compared to SAF occupational structure
B23: Census 1865 | C23: Census 1875 | D23: Census 1891 | E23: Census 1911
A24: White collar | B24: 29.747345 | C24: 33.81435 | D24: 27.926 | E24: 29.306956
A25: Farmer | B25: 55.33464 | C25: 52.637352 | D25: 52.399444 | E25: 47.827223
A26: Skilled/semi-skilled | B26: 7.4662267 | C26: 8.8066251 | D26: 17.676634 | E26: 19.034083
A27: Unskilled | B27: 7.4517892 | C27: 4.7416723 | D27: 1.9979219 | E27: 3.8317375
A28: Total working age pop | B28: 100 | C28: 100 | D28: 100 | E28: 100
